Workbook

Sheet TB
A3: 1 | B3: What Month? | O3: =A3 -> 1 | X3: =IF(A3-1 > 0, A3 - 1, 12) -> 12
A4: 2026 | B4: What Year? | O4: =A4-1 -> 2025 | X4: =IF(A3 = 1, A4-1, A4) -> 2025
B5: AccountNo | C5: Year | D5: Month | E5: YTD | F5: MTD | G5: Description | H5: Type | P5: AccountNo | Q5: Year | R5: Month | S5: YTD | T5: MTD | U5: Description | V5: Type | Y5: AccountNo | Z5: AccountField | AA5: YTD | AB5: MTD | AC5: Type | AD5: Description
B6: 1010101 | C6: 2026 | D6: 1 | E6: 5676709.9 | F6: 2500000 | G6: Cash In Bank - Money Market | H6: A | P6: 1010101 | Q6: 2025 | R6: 1 | S6: 5860198.8 | T6: 18597.1 | U6: Cash In Bank - Money Market | V6: A | Y6: 1010101 | Z6: Actual | AA6: 3176709.9 | AB6: -491755.12 | AC6: A | AD6: Cash In Bank - Money Market
B7: 1011001 | C7: 2026 | D7: 1 | E7: 1134287.9 | F7: -1039335.2 | G7: Cash In Bank - Checking | H7: A | P7: 1011001 | Q7: 2025 | R7: 1 | S7: 1374677.6 | T7: -726208.21 | U7: Cash In Bank - Checking | V7: A | Y7: 1011001 | Z7: Actual | AA7: 2173623.1 | AB7: 761514.13 | AC7: A | AD7: Cash In Bank - Checking
B8: 1014001 | C8: 2026 | D8: 1 | E8: 0 | F8: 0 | G8: Accounts Receivable-Other | H8: A | P8: 1014001 | Q8: 2025 | R8: 1 | S8: 0 | T8: 0 | U8: Accounts Receivable-Other | V8: A | Y8: 1014001 | Z8: Actual | AA8: 0 | AB8: 0 | AC8: A | AD8: Accounts Receivable-Other
B9: 1015001 | C9: 2026 | D9: 1 | E9: 0 | F9: 0 | G9: Accounts Receivable-Promler Properties | H9: A | P9: 1015001 | Q9: 2025 | R9: 1 | S9: 0 | T9: 0 | U9: Accounts Receivable-Promler Properties | V9: A | Y9: 1015001 | Z9: Actual | AA9: 0 | AB9: 0 | AC9: A | AD9: Accounts Receivable-Promler Properties
B10: 1016001 | C10: 2026 | D10: 1 | E10: 0 | F10: 0 | G10: Accounts Receivable-Ed Jr | H10: A | P10: 1016001 | Q10: 2025 | R10: 1 | S10: 0 | T10: 0 | U10: Accounts Receivable-Ed Jr | V10: A | Y10: 1016001 | Z10: Actual | AA10: 0 | AB10: 0 | AC10: A | AD10: Accounts Receivable-Ed Jr
B11: 1017001 | C11: 2026 | D11: 1 | E11: 0 | F11: 0 | G11: Accounts Receivable-Mark | H11: A | P11: 1017001 | Q11: 2025 | R11: 1 | S11: 0 | T11: 0 | U11: Accounts Receivable-Mark | V11: A | Y11: 1017001 | Z11: Actual | AA11: 0 | AB11: 0 | AC11: A | AD11: Accounts Receivable-Mark
B12: 1031001 | C12: 2026 | D12: 1 | E12: 1385493.2 | F12: -1078366.9 | G12: Accounts Receivable-Trade | H12: A | P12: 1031001 | Q12: 2025 | R12: 1 | S12: 2489058.2 | T12: 827347.32 | U12: Accounts Receivable-Trade | V12: A | Y12: 1031001 | Z12: Actual | AA12: 2463860.1 | AB12: -729029.03 | AC12: A | AD12: Accounts Receivable-Trade
B13: 1032001 | C13: 2026 | D13: 1 | E13: -2000.11 | F13: 0 | G13: Accounts Receivable-Employees | H13: A | P13: 1032001 | Q13: 2025 | R13: 1 | S13: -1918.43 | T13: 0 | U13: Accounts Receivable-Employees | V13: A | Y13: 1032001 | Z13: Actual | AA13: -2000.11 | AB13: -81.68 | AC13: A | AD13: Accounts Receivable-Employees
B14: 1110001 | C14: 2026 | D14: 1 | E14: 1550239.2 | F14: -391768.91 | G14: New Equipment Inventory | H14: A | P14: 1110001 | Q14: 2025 | R14: 1 | S14: 3148086.6 | T14: -242335.47 | U14: New Equipment Inventory | V14: A | Y14: 1110001 | Z14: Actual | AA14: 1942008.2 | AB14: 586927.23 | AC14: A | AD14: New Equipment Inventory
B15: 1120001 | C15: 2026 | D15: 1 | E15: 622576.08 | F15: 82970.2 | G15: Used Equipment Inventory | H15: A | P15: 1120001 | Q15: 2025 | R15: 1 | S15: 395371.73 | T15: 23483.72 | U15: Used Equipment Inventory | V15: A | Y15: 1120001 | Z15: Actual | AA15: 539605.88 | AB15: 1000 | AC15: A | AD15: Used Equipment Inventory
B16: 1120501 | C16: 2026 | D16: 1 | E16: 75346.38 | F16: -18331.89 | G16: AMI Used Equipment Inventory | H16: A | P16: 1120501 | Q16: 2025 | R16: 1 | S16: 113984.72 | T16: 42549.66 | U16: AMI Used Equipment Inventory | V16: A | Y16: 1120501 | Z16: Actual | AA16: 93678.27 | AB16: 900.66 | AC16: A | AD16: AMI Used Equipment Inventory
B17: 1129901 | C17: 2026 | D17: 1 | E17: 329107.42 | F17: 227563.21 | G17: Parts Inventory | H17: A | P17: 1129901 | Q17: 2025 | R17: 1 | S17: 429956.31 | T17: 111860.15 | U17: Parts Inventory | V17: A | Y17: 1129901 | Z17: Actual | AA17: 101544.21 | AB17: -240169.03 | AC17: A | AD17: Parts Inventory
... B752: 6980504 | C752: 2026 | D752: 1 | E752: 0 | F752: 0 | G752: G & A Allocation - DSS | H752: E | P752: 6990000 | Q752: 2025 | R752: 1 | S752: 0 | T752: 0 | U752: Deferred Income Tax Expense | V752: E | Y752: 6990000 | Z752: Actual | AA752: 0 | AB752: 0 | AC752: E | AD752: Deferred Income Tax Expense
B753: 6980601 | C753: 2026 | D753: 1 | E753: 0 | F753: 0 | G753: G & A Allocation | H753: E
B754: 6980602 | C754: 2026 | D754: 1 | E754: 0 | F754: 0 | G754: G & A Allocation | H754: E | S754: =SUBTOTAL(109,Table_TB1_1[YTD]) -> -1.1674274e-08 | T754: =SUBTOTAL(109,Table_TB1_1[MTD]) -> 4.3291948e-10
B755: 6980701 | C755: 2026 | D755: 1 | E755: 0 | F755: 0 | G755: G & A Allocation | H755: E
B756: 6980702 | C756: 2026 | D756: 1 | E756: 0 | F756: 0 | G756: G & A Allocation | H756: E
B757: 6980801 | C757: 2026 | D757: 1 | E757: 0 | F757: 0 | G757: G & A Allocation | H757: E
B758: 6980901 | C758: 2026 | D758: 1 | E758: 0 | F758: 0 | G758: G & A Allocation | H758: E
B759: 6980902 | C759: 2026 | D759: 1 | E759: 0 | F759: 0 | G759: G & A Allocation | H759: E
B760: 6990000 | C760: 2026 | D760: 1 | E760: 0 | F760: 0 | G760: Deferred Income Tax Expense | H760: E
E761: =SUBTOTAL(109,E6:E760) -> -7.6834112e-09 | F761: =SUBTOTAL(109,F6:F760) -> 6.9849193e-10

Sheet Balance Sheet
A1: Industrial Parts + Service Company
A2: Balance Sheet
A3: =DATEVALUE(TB!A3&"/"&TB!A4) -> 46023
C4: Assets | E4: YTD | G4: MTD
A5: 1010101 | C5: Cash In Bank - Money Market | E5: =VLOOKUP(A5,TB!TB,4,FALSE) -> 5676709.9 | G5: =VLOOKUP(A5,TB!TB,5,FALSE) -> 2500000
A6: 1011001 | C6: Cash In Bank - Checking | E6: =VLOOKUP(A6,TB!TB,4,FALSE) -> 1134287.9 | G6: =VLOOKUP(A6,TB!TB,5,FALSE) -> -1039335.2
C7: Total Checking | E7: =SUM(E5:E6) -> 6810997.8 | G7: =SUM(G5:G6) -> 1460664.8
A9: 1014001 | C9: Accounts Receivable-Other | E9: =VLOOKUP(A9,TB!TB,4,FALSE) -> 0 | G9: =VLOOKUP(A9,TB!TB,5,FALSE) -> 0
A10: 1031001 | C10: Accounts Receivable-Trade | E10: =VLOOKUP(A10,TB!TB,4,FALSE) -> 1385493.2 | G10: =VLOOKUP(A10,TB!TB,5,FALSE) -> -1078366.9
A11: 1032001 | C11: Accounts Receivable-Employees | E11: =VLOOKUP(A11,TB!TB,4,FALSE) -> -2000.11 | G11: =VLOOKUP(A11,TB!TB,5,FALSE) -> 0
A12: 1015001 | C12: Accounts Receivable-Promler Properties | E12: =VLOOKUP(A12,TB!TB,4,FALSE) -> 0 | G12: =VLOOKUP(A12,TB!TB,5,FALSE) -> 0
A13: 1016001 | C13: Accounts Receivable-Ed Jr | E13: =VLOOKUP(A13,TB!TB,4,FALSE) -> 0 | G13: =VLOOKUP(A13,TB!TB,5,FALSE) -> 0
A14: 1017001 | C14: Accounts Receivable-Mark | E14: =VLOOKUP(A14,TB!TB,4,FALSE) -> 0 | G14: =VLOOKUP(A14,TB!TB,5,FALSE) -> 0
C15: Total Receivable | E15: =SUM(E9:E14) -> 1383493.1 | G15: =SUM(G9:G14) -> -1078366.9
A17: 1110001 | C17: New Equipment Inventory | E17: =VLOOKUP(A17,TB!TB,4,FALSE) -> 1550239.2 | G17: =VLOOKUP(A17,TB!TB,5,FALSE) -> -391768.91
A18: 1120001 | C18: Used Equipment Inventory | E18: =VLOOKUP(A18,TB!TB,4,FALSE) -> 622576.08 | G18: =VLOOKUP(A18,TB!TB,5,FALSE) -> 82970.2
A19: 1120501 | C19: AMI Used Equipment Inventory | E19: =VLOOKUP(A19,TB!TB,4,FALSE) -> 75346.38 | G19: =VLOOKUP(A19,TB!TB,5,FALSE) -> -18331.89
A20: 1129901 | C20: Parts Inventory | E20: =VLOOKUP(A20,TB!TB,4,FALSE) -> 329107.42 | G20: =VLOOKUP(A20,TB!TB,5,FALSE) -> 227563.21
A21: 1140001 | C21: Allied Lines Inventory | E21: =VLOOKUP(A21,TB!TB,4,FALSE) -> 765025.01 | G21: =VLOOKUP(A21,TB!TB,5,FALSE) -> 258530.22
A22: 1150001 | C22: Work in Progress-Labor | E22: =VLOOKUP(A22,TB!TB,4,FALSE) -> 107823.53 | G22: =VLOOKUP(A22,TB!TB,5,FALSE) -> 56501.38
C23: Total Inventory | E23: =SUM(E17:E22) -> 3450117.7 | G23: =SUM(G17:G22) -> 215464.21
A25: 1600011 | C25: Clearing Account | E25: =VLOOKUP(A25,TB!TB,4,FALSE) -> 172.26 | G25: =VLOOKUP(A25,TB!TB,5,FALSE) -> 0
A26: 1210001 | C26: Prepaid Expense | E26: =VLOOKUP(A26,TB!TB,4,FALSE) -> 225.75 | G26: =VLOOKUP(A26,TB!TB,5,FALSE) -> 0
A27: 1213001 | C27: Prepaid Income Tax | E27: =VLOOKUP(A27,TB!TB,4,FALSE) -> 0 | G27: =VLOOKUP(A27,TB!TB,5,FALSE) -> 0
A28: 1216001 | C28: Prepaid Interest | E28: =VLOOKUP(A28,TB!TB,4,FALSE) -> 0 | G28: =VLOOKUP(A28,TB!TB,5,FALSE) -> 0
C29: Other Current Assets | E29: =SUM(E25:E28) -> 398.01 | G29: =SUM(G25:G28) -> 0
C31: Total Current Assets | E31: =E29+E23+E15+E7 -> 11645007 | G31: =G29+G23+G15+G7 -> 597762.04
A33: 1220001 | C33: Furniture and Fixtures-Shop | E33: =VLOOKUP(A33,TB!TB,4,FALSE) -> 70257.94 | G33: =VLOOKUP(A33,TB!TB,5,FALSE) -> 0
A34: 1230001 | C34: Furniture and Fixtures-Office | E34: =VLOOKUP(A34,TB!TB,4,FALSE) -> 330121.91 | G34: =VLOOKUP(A34,TB!TB,5,FALSE) -> 0
A35: 1241001 | C35: Furniture and Fixtures-Parts | E35: =VLOOKUP(A35,TB!TB,4,FALSE) -> 63994.71 | G35: =VLOOKUP(A35,TB!TB,5,FALSE) -> 0
A36: 1242001 | C36: Service Vehicles | E36: =VLOOKUP(A36,TB!TB,4,FALSE) -> 1979268.1 | G36: =VLOOKUP(A36,TB!TB,5,FALSE) -> 0
A37: 1240501 | C37: Demo Fleet | E37: =VLOOKUP(A37,TB!TB,4,FALSE) -> 744383.56 | G37: =VLOOKUP(A37,TB!TB,5,FALSE) -> -35911
A38: 1250001 | C38: Rental Fleet | E38: =VLOOKUP(A38,TB!TB,4,FALSE) -> 4777540.4 | G38: =VLOOKUP(A38,TB!TB,5,FALSE) -> 42574.25
A39: 1250101 | C39: AMI Lease Fleet | E39: =VLOOKUP(A39,TB!TB,4,FALSE) -> 21288661 | G39: =VLOOKUP(A39,TB!TB,5,FALSE) -> -46986.08
A40: 1250201 | C40: Used - AMI Return | E40: =VLOOKUP(A40,TB!TB,4,FALSE) -> 0 | G40: =VLOOKUP(A40,TB!TB,5,FALSE) -> 0
A41: 1250501 | C41: IPS Lease Fleet | E41: =VLOOKUP(A41,TB!TB,4,FALSE) -> 1335535.7 | G41: =VLOOKUP(A41,TB!TB,5,FALSE) -> 0
A42: 1260001 | C42: Leasehold Improvements | E42: =VLOOKUP(A42,TB!TB,4,FALSE) -> 34894.66 | G42: =VLOOKUP(A42,TB!TB,5,FALSE) -> 0
A43: 1513001 | C43: Accum.Depr.- F & E Shop | E43: =VLOOKUP(A43,TB!TB,4,FALSE) -> -67905.31 | G43: =VLOOKUP(A43,TB!TB,5,FALSE) -> -111.93
A44: 1514001 | C44: Accum.Depr.- F & E Office | E44: =VLOOKUP(A44,TB!TB,4,FALSE) -> -304567.86 | G44: =VLOOKUP(A44,TB!TB,5,FALSE) -> -1860.7
... A56: 1219000 | C56: Finance Lease-6440 Promler | E56: =VLOOKUP(A56,TB!TB,4,FALSE) -> 318755.7 | G56: =VLOOKUP(A56,TB!TB,5,FALSE) -> 0
...

Sheet Trial Balance
A1: Industrial Parts + Service Company
A2: Trial Balance
A3: =DATEVALUE(TB!$A$3&"/"&TB!$A$4) -> 46023
A5: Account # | B5: Type | C5: Account Name | E5: Begin Balance | G5: Period Debits | I5: Period Credits | K5: Net Change | M5: Ending Balance
A7: 1010101 | B7: A | C7: Cash In Bank - Money Market | E7: =VLOOKUP(A7,TB!TB2_,3,FALSE) -> 3176709.9 | G7: =VLOOKUP(A7,TB!TB2_,4,FALSE) -> -491755.12 | I7: =VLOOKUP(A7,TB!TB2_,4,FALSE) -> -491755.12 | K7: =I7+G7 -> -983510.24 | M7: =VLOOKUP(A7,TB!TB,4,FALSE) -> 5676709.9
A8: 1011001 | B8: A | C8: Cash In Bank - Checking | E8: =VLOOKUP(A8,TB!TB2_,3,FALSE) -> 2173623.1 | G8: =VLOOKUP(A8,TB!TB2_,4,FALSE) -> 761514.13 | I8: =VLOOKUP(A8,TB!TB2_,4,FALSE) -> 761514.13 | K8: =I8+G8 -> 1523028.3 | M8: =VLOOKUP(A8,TB!TB,4,FALSE) -> 1134287.9
A9: 1014001 | B9: A | C9: Accounts Receivable-Other | E9: =VLOOKUP(A9,TB!TB2_,3,FALSE) -> 0 | G9: =VLOOKUP(A9,TB!TB2_,4,FALSE) -> 0 | I9: =VLOOKUP(A9,TB!TB2_,4,FALSE) -> 0 | K9: =I9+G9 -> 0 | M9: =VLOOKUP(A9,TB!TB,4,FALSE) -> 0
A10: 1015001 | B10: A | C10: Accounts Receivable-Promler Properties | E10: =VLOOKUP(A10,TB!TB2_,3,FALSE) -> 0 | G10: =VLOOKUP(A10,TB!TB2_,4,FALSE) -> 0 | I10: =VLOOKUP(A10,TB!TB2_,4,FALSE) -> 0 | K10: =I10+G10 -> 0 | M10: =VLOOKUP(A10,TB!TB,4,FALSE) -> 0
A11: 1016001 | B11: A | C11: Accounts Receivable-Ed Jr | E11: =VLOOKUP(A11,TB!TB2_,3,FALSE) -> 0 | G11: =VLOOKUP(A11,TB!TB2_,4,FALSE) -> 0 | I11: =VLOOKUP(A11,TB!TB2_,4,FALSE) -> 0 | K11: =I11+G11 -> 0 | M11: =VLOOKUP(A11,TB!TB,4,FALSE) -> 0
A12: 1017001 | B12: A | C12: Accounts Receivable-Mark | E12: =VLOOKUP(A12,TB!TB2_,3,FALSE) -> 0 | G12: =VLOOKUP(A12,TB!TB2_,4,FALSE) -> 0 | I12: =VLOOKUP(A12,TB!TB2_,4,FALSE) -> 0 | K12: =I12+G12 -> 0 | M12: =VLOOKUP(A12,TB!TB,4,FALSE) -> 0
A13: 1031001 | B13: A | C13: Accounts Receivable-Trade | E13: =VLOOKUP(A13,TB!TB2_,3,FALSE) -> 2463860.1 | G13: =VLOOKUP(A13,TB!TB2_,4,FALSE) -> -729029.03 | I13: =VLOOKUP(A13,TB!TB2_,4,FALSE) -> -729029.03 | K13: =I13+G13 -> -1458058.1 | M13: =VLOOKUP(A13,TB!TB,4,FALSE) -> 1385493.2
A14: 1032001 | B14: A | C14: Accounts Receivable-Employees | E14: =VLOOKUP(A14,TB!TB2_,3,FALSE) -> -2000.11 | G14: =VLOOKUP(A14,TB!TB2_,4,FALSE) -> -81.68 | I14: =VLOOKUP(A14,TB!TB2_,4,FALSE) -> -81.68 | K14: =I14+G14 -> -163.36 | M14: =VLOOKUP(A14,TB!TB,4,FALSE) -> -2000.11
A15: 1016001 | B15: A | C15: Accounts Receivable-Ed Jr | E15: =VLOOKUP(A15,TB!TB2_,3,FALSE) -> 0 | G15: =VLOOKUP(A15,TB!TB2_,4,FALSE) -> 0 | I15: =VLOOKUP(A15,TB!TB2_,4,FALSE) -> 0 | K15: =I15+G15 -> 0 | M15: =VLOOKUP(A15,TB!TB,4,FALSE) -> 0
A16: 1017001 | B16: A | C16: Accounts Receivable-Mark | E16: =VLOOKUP(A16,TB!TB2_,3,FALSE) -> 0 | G16: =VLOOKUP(A16,TB!TB2_,4,FALSE) -> 0 | I16: =VLOOKUP(A16,TB!TB2_,4,FALSE) -> 0 | K16: =I16+G16 -> 0 | M16: =VLOOKUP(A16,TB!TB,4,FALSE) -> 0
A17: 1110001 | B17: A | C17: New Equipment Inventory | E17: =VLOOKUP(A17,TB!TB2_,3,FALSE) -> 1942008.2 | G17: =VLOOKUP(A17,TB!TB2_,4,FALSE) -> 586927.23 | I17: =VLOOKUP(A17,TB!TB2_,4,FALSE) -> 586927.23 | K17: =I17+G17 -> 1173854.5 | M17: =VLOOKUP(A17,TB!TB,4,FALSE) -> 1550239.2
A18: 1120001 | B18: A | C18: Used Equipment Inventory | E18: =VLOOKUP(A18,TB!TB2_,3,FALSE) -> 539605.88 | G18: =VLOOKUP(A18,TB!TB2_,4,FALSE) -> 1000 | I18: =VLOOKUP(A18,TB!TB2_,4,FALSE) -> 1000 | K18: =I18+G18 -> 2000 | M18: =VLOOKUP(A18,TB!TB,4,FALSE) -> 622576.08
... A49: 2030301 | B49: L | C49: Notes Payable L.T.-Other | E49: =VLOOKUP(A49,TB!TB2_,3,FALSE) -> 0 | G49: =VLOOKUP(A49,TB!TB2_,4,FALSE) -> 0 | I49: =VLOOKUP(A49,TB!TB2_,4,FALSE) -> 0 | K49: =I49+G49 -> 0 | M49: =VLOOKUP(A49,TB!TB,4,FALSE) -> 0
A50: 2030303 | B50: L | C50: Note - Ed Mauser Jr | E50: 0 | G50: 0 | I50: 0 | K50: 0 | M50: 0
A51: 2041901 | B51: L | C51: Paycheck Protection-Credit Line | E51: =VLOOKUP(A51,TB!TB2_,3,FALSE) -> 0 | G51: =VLOOKUP(A51,TB!TB2_,4,FALSE) -> 0 | I51: =VLOOKUP(A51,TB!TB2_,4,FALSE) -> 0 | K51: =I51+G51 -> 0 | M51: =VLOOKUP(A51,TB!TB,4,FALSE) -> 0
A52: 2042001 | B52: L | C52: Notes Payable-Credit Line | E52: =VLOOKUP(A52,TB!TB2_,3,FALSE) -> 0 | G52: =VLOOKUP(A52,TB!TB2_,4,FALSE) -> 0 | I52: =VLOOKUP(A52,TB!TB2_,4,FALSE) -> 0 | K52: =I52+G52 -> 0 | M52: =VLOOKUP(A52,TB!TB,4,FALSE) -> 0
A53: 2042101 | B53: L | C53: Notes Payable S T Other | E53: =VLOOKUP(A53,TB!TB2_,3,FALSE) -> 0 | G53: =VLOOKUP(A53,TB!TB2_,4,FALSE) -> 0 | I53: =VLOOKUP(A53,TB!TB2_,4,FALSE) -> 0 | K53: =I53+G53 -> 0 | M53: =VLOOKUP(A53,TB!TB,4,FALSE) -> 0
A54: 2042102 | B54: L | C54: Note Payable Mark Mauser - Current | E54: =VLOOKUP(A54,TB!TB2_,3,FALSE) -> -408353.3 | G54: =VLOOKUP(A54,TB!TB2_,4,FALSE) -> 0 | I54: =VLOOKUP(A54,TB!TB2_,4,FALSE) -> 0 | K54: =I54+G54 -> 0 | M54: =VLOOKUP(A54,TB!TB,4,FALSE) -> -408353.3
A55: 2042201 | B55: L | C55: Notes Payable S.T. Floorplan | E55: =VLOOKUP(A55,TB!TB2_,3,FALSE) -> 365.91 | G55: =VLOOKUP(A55,TB!TB2_,4,FALSE) -> 0 | I55: =VLOOKUP(A55,TB!TB2_,4,FALSE) -> 0 | K55: =I55+G55 -> 0 | M55: =VLOOKUP(A55,TB!TB,4,FALSE) -> 365.91
A56: 2049501 | B56: L | C56: Suspense Account | E56: =VLOOKUP(A56,TB!TB2_,3,FALSE) -> 0 | G56: =VLOOKUP(A56,TB!TB2_,4,FALSE) -> 0 | I56: =VLOOKUP(A56,TB!TB2_,4,FALSE) -> 0 | K56: =I56+G56 -> 0 | M56: =VLOOKUP(A56,TB!TB,4,FALSE) -> 0
A57: 2050001 | B57: L | C57: Accounts Payable Trade | E57: =VLOOKUP(A57,TB!TB2_,3,FALSE) -> -1846587.7 | G57: =VLOOKUP(A57,TB!TB2_,4,FALSE) -> 556061.5 | I57: =VLOOKUP(A57,TB!TB2_,4,FALSE) -> 556061.5 | K57: =I57+G57 -> 1112123 | M57: =VLOOKUP(A57,TB!TB,4,FALSE) -> -2146398.3
A58: 2051001 | B58: L | C58: Accounts Payable Credit Card | E58: =VLOOKUP(A58,TB!TB2_,3,FALSE) -> 0 | G58: =VLOOKUP(A58,TB!TB2_,4,FALSE) -> 0 | I58: =VLOOKUP(A58,TB!TB2_,4,FALSE) -> 0 | K58: =I58+G58 -> 0 | M58: =VLOOKUP(A58,TB!TB,4,FALSE) -> 0
A59: 2071001 | B59: L | C59: Accrued Federal Withholding | E59: =VLOOKUP(A59,TB!TB2_,3,FALSE) -> 0 | G59: =VLOOKUP(A59,TB!TB2_,4,FALSE) -> 0 | I59: =VLOOKUP(A59,TB!TB2_,4,FALSE) -> 0 | K59: =I59+G59 -> 0 | M59: =VLOOKUP(A59,TB!TB,4,FALSE) -> 0
A60: 2072001 | B60: L | C60: Accrued FICA Employer | E60: =VLOOKUP(A60,TB!TB2_,3,FALSE) -> -12017.73 | G60: =VLOOKUP(A60,TB!TB2_,4,FALSE) -> 0 | I60: =VLOOKUP(A60,TB!TB2_,4,FALSE) -> 0 | K60: =I60+G60 -> 0 | M60: =VLOOKUP(A60,TB!TB,4,FALSE) -> -12017.73
A61: 2073001 | B61: L | C61: Accrues State Withholding | E61: =VLOOKUP(A61,TB!TB2_,3,FALSE) -> 0 | G61: =VLOOKUP(A61,TB!TB2_,4,FALSE) -> 0 | I61: =VLOOKUP(A61,TB!TB2_,4,FALSE) -> 0 | K61: =I61+G61 -> 0 | M61: =VLOOKUP(A61,TB!TB,4,FALSE) -> 0
A62: 2073501 | B62: L | C62: Accrued School Income Tax | E62: =VLOOKUP(A62,TB!TB2_,3,FALSE) -> 0 | G62: =VLOOKUP(A62,TB!TB2_,4,FALSE) -> 0 | I62: =VLOOKUP(A62,TB!TB2_,4,FALSE) -> 0 | K62: =I62+G62 -> 0 | M62: =VLOOKUP(A62,TB!TB,4,FALSE) -> 0
... A81: 2080010 | B81: L | C81: Sales Tax Payable - Minnisota | E81: =VLOOKUP(A81,TB!TB2_,3,FALSE) -> -3264.7 | G81: =VLOOKUP(A81,TB!TB2_,4,FALSE) -> 0 | I81: =VLOOKUP(A81,TB!TB2_,4,FALSE) -> 0 | K81: =I81+G81 -> 0 | M81: =VLOOKUP(A81,TB!TB,4,FALSE) -> -3264.7
A83: Industrial Parts + Service Company
A84: Trial Balance
A85: =DATEVALUE(TB!$A$3&"/"&TB!$A$4) -> 46023
A86: 2080011 | B86: L | C86: Sales Tax Payable - Missouri | E86: =VLOOKUP(A86,TB!TB2_,3,FALSE) -> -8179.88 | G86: =VLOOKUP(A86,TB!TB2_,4,FALSE) -> 0 | I86: =VLOOKUP(A86,TB!TB2_,4,FALSE) -> 0 | K86: =I86+G86 -> 0 | M86: =VLOOKUP(A86,TB!TB,4,FALSE) -> -8179.88
A87: 2080012 | B87: L | C87: Sales Tax Payable - Oklahoma | E87: =VLOOKUP(A87,TB!TB2_,3,FALSE) -> -1439.9 | G87: =VLOOKUP(A87,TB!TB2_,4,FALSE) -> -1289.06 | I87: =VLOOKUP(A87,TB!TB2_,4,FALSE) -> -1289.06 | K87: =I87+G87 -> -2578.12 | M87: =VLOOKUP(A87,TB!TB,4,FALSE) -> -10193.25
A88: 2080013 | B88: L | C88: Sales Tax Payable - Texas | E88: =VLOOKUP(A88,TB!TB2_,3,FALSE) -> -11446.54 | G88: =VLOOKUP(A88,TB!TB2_,4,FALSE) -> 35273.56 | I88: =VLOOKUP(A88,TB!TB2_,4,FALSE) -> 35273.56 | K88: =I88+G88 -> 70547.12 | M88: =VLOOKUP(A88,TB!TB,4,FALSE) -> -270.98
A89: 2080014 | B89: L | C89: Sales Tax Payable - Virginia | E89: =VLOOKUP(A89,TB!TB2_,3,FALSE) -> 0 | G89: =VLOOKUP(A89,TB!TB2_,4,FALSE) -> 0 | I89: =VLOOKUP(A89,TB!TB2_,4,FALSE) -> 0 | K89: =I89+G89 -> 0 | M89: =VLOOKUP(A89,TB!TB,4,FALSE) -> 0
A90: 2080015 | B90: L | C90: Sales Tax Payable - Washington | E90: =VLOOKUP(A90,TB!TB2_,3,FALSE) -> -26028.48 | G90: =VLOOKUP(A90,TB!TB2_,4,FALSE) -> -8213.92 | I90: =VLOOKUP(A90,TB!TB2_,4,FALSE) -> -8213.92 | K90: =I90+G90 -> -16427.84 | M90: =VLOOKUP(A90,TB!TB,4,FALSE) -> -7691.18
A91: 2080016 | B91: L | C91: Sales Tax Payable - West Virginia | E91: =VLOOKUP(A91,TB!TB2_,3,FALSE) -> -376.08 | G91: =VLOOKUP(A91,TB!TB2_,4,FALSE) -> 0 | I91: =VLOOKUP(A91,TB!TB2_,4,FALSE) -> 0 | K91: =I91+G91 -> 0 | M91: =VLOOKUP(A91,TB!TB,4,FALSE) -> -356.78
...

Sheet Combined Detail P and L
A1: Industrial Parts + Service Company
A2: Consolidated Detail P and L
A3: =DATEVALUE(TB!A3&"/"&TB!A4) -> 46023
C4: Description | E4: =TB!O4 -> 2025 | H4: =TB!A4 -> 2026 | K4: =TB!O4 -> 2025 | N4: =TB!A4 -> 2026
A5: Account # | C5: Revenue | E5: MTD | F5: % of Sales | H5: MTD | I5: % of Sales | K5: YTD | L5: % of Sales | N5: YTD | O5: % of Sales
A7: 4036503 | C7: Parts Sales to CH Steel | E7: =VLOOKUP(A7,TB!TB1_1,5,FALSE)*-1 -> 0 | F7: =IF(E$160,E7/E$160,0) -> 0 | H7: =VLOOKUP(A7,TB!TB,5,FALSE)*-1 -> 0 | I7: =IF(H$160,H7/H$160,0) -> 0 | K7: =VLOOKUP(A7,TB!TB1_1,4,FALSE)*-1 -> 0 | L7: =IF(K$160,K7/K$160,0) -> 0 | N7: =VLOOKUP(A7,TB!TB,4,FALSE)*-1 -> 0 | O7: =IF(N$160,N7/N$160,0) -> 0
A8: 4110501 | C8: New Equipment Linde - Canton | E8: =VLOOKUP(A8,TB!TB1_1,5,FALSE)*-1 -> 73800 | F8: =IF(E$160,E8/E$160,0) -> 0.024947055 | H8: =VLOOKUP(A8,TB!TB,5,FALSE)*-1 -> 239550 | I8: =IF(H$160,H8/H$160,0) -> 0.10868515 | K8: =VLOOKUP(A8,TB!TB1_1,4,FALSE)*-1 -> 73800 | L8: =IF(K$160,K8/K$160,0) -> 0.024947055 | N8: =VLOOKUP(A8,TB!TB,4,FALSE)*-1 -> 239550 | O8: =IF(N$160,N8/N$160,0) -> 0.10868515
A9: 4110502 | C9: New Equipment Linde - Cleveland | E9: =VLOOKUP(A9,TB!TB1_1,5,FALSE)*-1 -> 114900 | F9: =IF(E$160,E9/E$160,0) -> 0.038840333 | H9: =VLOOKUP(A9,TB!TB,5,FALSE)*-1 -> 111968 | I9: =IF(H$160,H9/H$160,0) -> 0.050800498 | K9: =VLOOKUP(A9,TB!TB1_1,4,FALSE)*-1 -> 114900 | L9: =IF(K$160,K9/K$160,0) -> 0.038840333 | N9: =VLOOKUP(A9,TB!TB,4,FALSE)*-1 -> 111968 | O9: =IF(N$160,N9/N$160,0) -> 0.050800498
A10: 4110503 | C10: New Equipment Linde - C H Steel | E10: =VLOOKUP(A10,TB!TB1_1,5,FALSE)*-1 -> 0 | F10: =IF(E$160,E10/E$160,0) -> 0 | H10: =VLOOKUP(A10,TB!TB,5,FALSE)*-1 -> 0 | I10: =IF(H$160,H10/H$160,0) -> 0 | K10: =VLOOKUP(A10,TB!TB1_1,4,FALSE)*-1 -> 0 | L10: =IF(K$160,K10/K$160,0) -> 0 | N10: =VLOOKUP(A10,TB!TB,4,FALSE)*-1 -> 0 | O10: =IF(N$160,N10/N$160,0) -> 0
A11: 4110504 | C11: New Equipment Linde - DSS | E11: =VLOOKUP(A11,TB!TB1_1,5,FALSE)*-1 -> 0 | F11: =IF(E$160,E11/E$160,0) -> 0 | H11: =VLOOKUP(A11,TB!TB,5,FALSE)*-1 -> 0 | I11: =IF(H$160,H11/H$160,0) -> 0 | K11: =VLOOKUP(A11,TB!TB1_1,4,FALSE)*-1 -> 0 | L11: =IF(K$160,K11/K$160,0) -> 0 | N11: =VLOOKUP(A11,TB!TB,4,FALSE)*-1 -> 0 | O11: =IF(N$160,N11/N$160,0) -> 0
A12: 4112001 | C12: Commission-Allied - Canton | E12: =VLOOKUP(A12,TB!TB1_1,5,FALSE)*-1 -> 0 | F12: =IF(E$160,E12/E$160,0) -> 0 | H12: =VLOOKUP(A12,TB!TB,5,FALSE)*-1 -> 0 | I12: =IF(H$160,H12/H$160,0) -> 0 | K12: =VLOOKUP(A12,TB!TB1_1,4,FALSE)*-1 -> 0 | L12: =IF(K$160,K12/K$160,0) -> 0 | N12: =VLOOKUP(A12,TB!TB,4,FALSE)*-1 -> 0 | O12: =IF(N$160,N12/N$160,0) -> 0
A13: 4112002 | C13: Commission-Allied - Cleveland | E13: =VLOOKUP(A13,TB!TB1_1,5,FALSE)*-1 -> 0 | F13: =IF(E$160,E13/E$160,0) -> 0 | H13: =VLOOKUP(A13,TB!TB,5,FALSE)*-1 -> 0 | I13: =IF(H$160,H13/H$160,0) -> 0 | K13: =VLOOKUP(A13,TB!TB1_1,4,FALSE)*-1 -> 0 | L13: =IF(K$160,K13/K$160,0) -> 0 | N13: =VLOOKUP(A13,TB!TB,4,FALSE)*-1 -> 0 | O13: =IF(N$160,N13/N$160,0) -> 0
A14: 4112203 | C14: Commission-Allied - CH Steel | E14: =VLOOKUP(A14,TB!TB1_1,5,FALSE)*-1 -> 0 | F14: =IF(E$160,E14/E$160,0) -> 0 | H14: =VLOOKUP(A14,TB!TB,5,FALSE)*-1 -> 0 | I14: =IF(H$160,H14/H$160,0) -> 0 | K14: =VLOOKUP(A14,TB!TB1_1,4,FALSE)*-1 -> 0 | L14: =IF(K$160,K14/K$160,0) -> 0 | N14: =VLOOKUP(A14,TB!TB,4,FALSE)*-1 -> 0 | O14: =IF(N$160,N14/N$160,0) -> 0
A15: 4112204 | C15: Commission-Allied - DSS | E15: =VLOOKUP(A15,TB!TB1_1,5,FALSE)*-1 -> 0 | F15: =IF(E$160,E15/E$160,0) -> 0 | H15: =VLOOKUP(A15,TB!TB,5,FALSE)*-1 -> 0 | I15: =IF(H$160,H15/H$160,0) -> 0 | K15: =VLOOKUP(A15,TB!TB1_1,4,FALSE)*-1 -> 0 | L15: =IF(K$160,K15/K$160,0) -> 0 | N15: =VLOOKUP(A15,TB!TB,4,FALSE)*-1 -> 0 | O15: =IF(N$160,N15/N$160,0) -> 0
A16: 4111401 | C16: Commission-Used Equipment - Canton | E16: =VLOOKUP(A16,TB!TB1_1,5,FALSE)*-1 -> 0 | F16: =IF(E$160,E16/E$160,0) -> 0 | H16: =VLOOKUP(A16,TB!TB,5,FALSE)*-1 -> 0 | I16: =IF(H$160,H16/H$160,0) -> 0 | K16: =VLOOKUP(A16,TB!TB1_1,4,FALSE)*-1 -> 0 | L16: =IF(K$160,K16/K$160,0) -> 0 | N16: =VLOOKUP(A16,TB!TB,4,FALSE)*-1 -> 0 | O16: =IF(N$160,N16/N$160,0) -> 0
A17: 4111402 | C17: Commission-Used Equipment - Cleveland | E17: =VLOOKUP(A17,TB!TB1_1,5,FALSE)*-1 -> 0 | F17: =IF(E$160,E17/E$160,0) -> 0 | H17: =VLOOKUP(A17,TB!TB,5,FALSE)*-1 -> 0 | I17: =IF(H$160,H17/H$160,0) -> 0 | K17: =VLOOKUP(A17,TB!TB1_1,4,FALSE)*-1 -> 0 | L17: =IF(K$160,K17/K$160,0) -> 0 | N17: =VLOOKUP(A17,TB!TB,4,FALSE)*-1 -> 0 | O17: =IF(N$160,N17/N$160,0) -> 0
A18: 4111403 | C18: Commission-Used Equipment - CH Steel | E18: =VLOOKUP(A18,TB!TB1_1,5,FALSE)*-1 -> 0 | F18: =IF(E$160,E18/E$160,0) -> 0 | H18: =VLOOKUP(A18,TB!TB,5,FALSE)*-1 -> 0 | I18: =IF(H$160,H18/H$160,0) -> 0 | K18: =VLOOKUP(A18,TB!TB1_1,4,FALSE)*-1 -> 0 | L18: =IF(K$160,K18/K$160,0) -> 0 | N18: =VLOOKUP(A18,TB!TB,4,FALSE)*-1 -> 0 | O18: =IF(N$160,N18/N$160,0) -> 0
... A44: 4126602 | C44: Combi Parts Sale - Cleveland | E44: =VLOOKUP(A44,TB!TB1_1,5,FALSE)*-1 -> 0 | F44: =IF(E$160,E44/E$160,0) -> 0 | H44: =VLOOKUP(A44,TB!TB,5,FALSE)*-1 -> 0 | I44: =IF(H$160,H44/H$160,0) -> 0 | K44: =VLOOKUP(A44,TB!TB1_1,4,FALSE)*-1 -> 0 | L44: =IF(K$160,K44/K$160,0) -> 0 | N44: =VLOOKUP(A44,TB!TB,4,FALSE)*-1 -> 0 | O44: =IF(N$160,N44/N$160,0) -> 0
A45: 4146601 | C45: TVH Parts Sale - Canton | E45: 0 | F45: =IF(E$160,E45/E$160,0) -> 0 | H45: =VLOOKUP(A45,TB!TB,5,FALSE)*-1 -> 2046.32 | I45: =IF(H$160,H45/H$160,0) -> 0.00092842665 | K45: 0 | L45: =IF(K$160,K45/K$160,0) -> 0 | N45: =VLOOKUP(A45,TB!TB,4,FALSE)*-1 -> 2046.32 | O45: =IF(N$160,N45/N$160,0) -> 0.00092842665
A46: 4127601 | C46: Tire Sale - Canton | E46: =VLOOKUP(A46,TB!TB1_1,5,FALSE)*-1 -> 1272.33 | F46: =IF(E$160,E46/E$160,0) -> 0.00043009331 | H46: =VLOOKUP(A46,TB!TB,5,FALSE)*-1 -> 0 | I46: =IF(H$160,H46/H$160,0) -> 0 | K46: =VLOOKUP(A46,TB!TB1_1,4,FALSE)*-1 -> 1272.33 | L46: =IF(K$160,K46/K$160,0) -> 0.00043009331 | N46: =VLOOKUP(A46,TB!TB,4,FALSE)*-1 -> 0 | O46: =IF(N$160,N46/N$160,0) -> 0
A47: 4127602 | C47: Tire Sale - Cleveland | E47: =VLOOKUP(A47,TB!TB1_1,5,FALSE)*-1 -> 0 | F47: =IF(E$160,E47/E$160,0) -> 0 | H47: =VLOOKUP(A47,TB!TB,5,FALSE)*-1 -> 0 | I47: =IF(H$160,H47/H$160,0) -> 0 | K47: =VLOOKUP(A47,TB!TB1_1,4,FALSE)*-1 -> 0 | L47: =IF(K$160,K47/K$160,0) -> 0 | N47: =VLOOKUP(A47,TB!TB,4,FALSE)*-1 -> 0 | O47: =IF(N$160,N47/N$160,0) -> 0
A48: 4128601 | C48: Freight - Parts - Canton | E48: =VLOOKUP(A48,TB!TB1_1,5,FALSE)*-1 -> 10554.19 | F48: =IF(E$160,E48/E$160,0) -> 0.0035676959 | H48: =VLOOKUP(A48,TB!TB,5,FALSE)*-1 -> 7977.85 | I48: =IF(H$160,H48/H$160,0) -> 0.0036195944 | K48: =VLOOKUP(A48,TB!TB1_1,4,FALSE)*-1 -> 10554.19 | L48: =IF(K$160,K48/K$160,0) -> 0.0035676959 | N48: =VLOOKUP(A48,TB!TB,4,FALSE)*-1 -> 7977.85 | O48: =IF(N$160,N48/N$160,0) -> 0.0036195944
A49: 4128602 | C49: Freight - Parts - Cleveland | E49: =VLOOKUP(A49,TB!TB1_1,5,FALSE)*-1 -> 0 | F49: =IF(E$160,E49/E$160,0) -> 0 | H49: =VLOOKUP(A49,TB!TB,5,FALSE)*-1 -> 0 | I49: =IF(H$160,H49/H$160,0) -> 0 | K49: =VLOOKUP(A49,TB!TB1_1,4,FALSE)*-1 -> 0 | L49: =IF(K$160,K49/K$160,0) -> 0 | N49: =VLOOKUP(A49,TB!TB,4,FALSE)*-1 -> 0 | O49: =IF(N$160,N49/N$160,0) -> 0
A50: 4129601 | C50: Parts Sale Other - Canton | E50: =VLOOKUP(A50,TB!TB1_1,5,FALSE)*-1 -> 52716.39 | F50: =IF(E$160,E50/E$160,0) -> 0.017820036 | H50: =VLOOKUP(A50,TB!TB,5,FALSE)*-1 -> 42014.11 | I50: =IF(H$160,H50/H$160,0) -> 0.019062033 | K50: =VLOOKUP(A50,TB!TB1_1,4,FALSE)*-1 -> 52716.39 | L50: =IF(K$160,K50/K$160,0) -> 0.017820036 | N50: =VLOOKUP(A50,TB!TB,4,FALSE)*-1 -> 42014.11 | O50: =IF(N$160,N50/N$160,0) -> 0.019062033
A51: 4129602 | C51: Parts Sale Other - Cleveland | E51: =VLOOKUP(A51,TB!TB1_1,5,FALSE)*-1 -> 0 | F51: =IF(E$160,E51/E$160,0) -> 0 | H51: =VLOOKUP(A51,TB!TB,5,FALSE)*-1 -> 0 | I51: =IF(H$160,H51/H$160,0) -> 0 | K51: =VLOOKUP(A51,TB!TB1_1,4,FALSE)*-1 -> 0 | L51: =IF(K$160,K51/K$160,0) -> 0 | N51: =VLOOKUP(A51,TB!TB,4,FALSE)*-1 -> 0 | O51: =IF(N$160,N51/N$160,0) -> 0
A52: 4130601 | C52: Shop Parts-Linde - Canton | E52: =VLOOKUP(A52,TB!TB1_1,5,FALSE)*-1 -> 5050.8 | F52: =IF(E$160,E52/E$160,0) -> 0.0017073521 | H52: =VLOOKUP(A52,TB!TB,5,FALSE)*-1 -> 13032.79 | I52: =IF(H$160,H52/H$160,0) -> 0.0059130485 | K52: =VLOOKUP(A52,TB!TB1_1,4,FALSE)*-1 -> 5050.8 | L52: =IF(K$160,K52/K$160,0) -> 0.0017073521 | N52: =VLOOKUP(A52,TB!TB,4,FALSE)*-1 -> 13032.79 | O52: =IF(N$160,N52/N$160,0) -> 0.0059130485
A53: 4130602 | C53: Shop Parts-Linde - Cleveland | E53: =VLOOKUP(A53,TB!TB1_1,5,FALSE)*-1 -> 0 | F53: =IF(E$160,E53/E$160,0) -> 0 | H53: =VLOOKUP(A53,TB!TB,5,FALSE)*-1 -> 0 | I53: =IF(H$160,H53/H$160,0) -> 0 | K53: =VLOOKUP(A53,TB!TB1_1,4,FALSE)*-1 -> 0 | L53: =IF(K$160,K53/K$160,0) -> 0 | N53: =VLOOKUP(A53,TB!TB,4,FALSE)*-1 -> 0 | O53: =IF(N$160,N53/N$160,0) -> 0
A54: 4131601 | C54: Shop Parts-Combi - Canton | E54: =VLOOKUP(A54,TB!TB1_1,5,FALSE)*-1 -> -360.16 | F54: =IF(E$160,E54/E$160,0) -> -0.00012174704 | H54: =VLOOKUP(A54,TB!TB,5,FALSE)*-1 -> 1044.46 | I54: =IF(H$160,H54/H$160,0) -> 0.00047387725 | K54: =VLOOKUP(A54,TB!TB1_1,4,FALSE)*-1 -> -360.16 | L54: =IF(K$160,K54/K$160,0) -> -0.00012174704 | N54: =VLOOKUP(A54,TB!TB,4,FALSE)*-1 -> 1044.46 | O54: =IF(N$160,N54/N$160,0) -> 0.00047387725
A55: 4131602 | C55: Shop Parts-Combi - Cleveland | E55: =VLOOKUP(A55,TB!TB1_1,5,FALSE)*-1 -> 0 | F55: =IF(E$160,E55/E$160,0) -> 0 | H55: =VLOOKUP(A55,TB!TB,5,FALSE)*-1 -> 0 | I55: =IF(H$160,H55/H$160,0) -> 0 | K55: =VLOOKUP(A55,TB!TB1_1,4,FALSE)*-1 -> 0 | L55: =IF(K$160,K55/K$160,0) -> 0 | N55: =VLOOKUP(A55,TB!TB,4,FALSE)*-1 -> 0 | O55: =IF(N$160,N55/N$160,0) -> 0
A56: 4141601 | C56: Shop Parts-TVH - Canton | E56: 0 | F56: =IF(E$160,E56/E$160,0) -> 0 | H56: =VLOOKUP(A56,TB!TB,5,FALSE)*-1 -> 357.17 | I56: =IF(H$160,H56/H$160,0) -> 0.00016204999 | K56: 0 | L56: =IF(K$160,K56/K$160,0) -> 0 | N56: =VLOOKUP(A56,TB!TB,4,FALSE)*-1 -> 357.17 | O56: =IF(N$160,N56/N$160,0) -> 0.00016204999
A57: 4132601 | C57: Shop Parts-Other - Canton | E57: =VLOOKUP(A57,TB!TB1_1,5,FALSE)*-1 -> 17214.34 | F57: =IF(E$160,E57/E$160,0) -> 0.0058190661 | H57: =VLOOKUP(A57,TB!TB,5,FALSE)*-1 -> 9825.13 | I57: =IF(H$160,H57/H$160,0) -> 0.0044577156 | K57: =VLOOKUP(A57,TB!TB1_1,4,FALSE)*-1 -> 17214.34 | L57: =IF(K$160,K57/K$160,0) -> 0.0058190661 | N57: =VLOOKUP(A57,TB!TB,4,FALSE)*-1 -> 9825.13 | O57: =IF(N$160,N57/N$160,0) -> 0.0044577156
A58: 4132602 | C58: Shop Parts-Other - Cleveland | E58: =VLOOKUP(A58,TB!TB1_1,5,FALSE)*-1 -> 0 | F58: =IF(E$160,E58/E$160,0) -> 0 | H58: =VLOOKUP(A58,TB!TB,5,FALSE)*-1 -> 0 | I58: =IF(H$160,H58/H$160,0) -> 0 | K58: =VLOOKUP(A58,TB!TB1_1,4,FALSE)*-1 -> 0 | L58: =IF(K$160,K58/K$160,0) -> 0 | N58: =VLOOKUP(A58,TB!TB,4,FALSE)*-1 -> 0 | O58: =IF(N$160,N58/N$160,0) -> 0
A59: 4133601 | C59: Road Parts-Linde - Canton | E59: =VLOOKUP(A59,TB!TB1_1,5,FALSE)*-1 -> 31657.28 | F59: =IF(E$160,E59/E$160,0) -> 0.010701299 | H59: =VLOOKUP(A59,TB!TB,5,FALSE)*-1 -> 26290.97 | I59: =IF(H$160,H59/H$160,0) -> 0.011928358 | K59: =VLOOKUP(A59,TB!TB1_1,4,FALSE)*-1 -> 31657.28 | L59: =IF(K$160,K59/K$160,0) -> 0.010701299 | N59: =VLOOKUP(A59,TB!TB,4,FALSE)*-1 -> 26290.97 | O59: =IF(N$160,N59/N$160,0) -> 0.011928358
A60: 4133602 | C60: Road Parts-Linde - Cleveland | E60: =VLOOKUP(A60,TB!TB1_1,5,FALSE)*-1 -> 0 | F60: =IF(E$160,E60/E$160,0) -> 0 | H60: =VLOOKUP(A60,TB!TB,5,FALSE)*-1 -> 0 | I60: =IF(H$160,H60/H$160,0) -> 0 | K60: =VLOOKUP(A60,TB!TB1_1,4,FALSE)*-1 -> 0 | L60: =IF(K$160,K60/K$160,0) -> 0 | N60: =VLOOKUP(A60,TB!TB,4,FALSE)*-1 -> 0 | O60: =IF(N$160,N60/N$160,0) -> 0
A61: 4134601 | C61: Road Parts-Combi - Canton | E61: =VLOOKUP(A61,TB!TB1_1,5,FALSE)*-1 -> 13408.77 | F61: =IF(E$160,E61/E$160,0) -> 0.0045326466 | H61: =VLOOKUP(A61,TB!TB,5,FALSE)*-1 -> 17981.82 | I61: =IF(H$160,H61/H$160,0) -> 0.0081584507 | K61: =VLOOKUP(A61,TB!TB1_1,4,FALSE)*-1 -> 13408.77 | L61: =IF(K$160,K61/K$160,0) -> 0.0045326466 | N61: =VLOOKUP(A61,TB!TB,4,FALSE)*-1 -> 17981.82 | O61: =IF(N$160,N61/N$160,0) -> 0.0081584507
A62: 4134602 | C62: Road Parts-Combi - Cleveland | E62: =VLOOKUP(A62,TB!TB1_1,5,FALSE)*-1 -> 0 | F62: =IF(E$160,E62/E$160,0) -> 0 | H62: =VLOOKUP(A62,TB!TB,5,FALSE)*-1 -> 0 | I62: =IF(H$160,H62/H$160,0) -> 0 | K62: =VLOOKUP(A62,TB!TB1_1,4,FALSE)*-1 -> 0 | L62: =IF(K$160,K62/K$160,0) -> 0 | N62: =VLOOKUP(A62,TB!TB,4,FALSE)*-1 -> 0 | O62: =IF(N$160,N62/N$160,0) -> 0
A63: 4144601 | C63: Road Parts-TVH - Canton | E63: 0 | F63: =IF(E$160,E63/E$160,0) -> 0 | H63: =VLOOKUP(A63,TB!TB,5,FALSE)*-1 -> 565.2 | I63: =IF(H$160,H63/H$160,0) -> 0.00025643435 | K63: 0 | L63: =IF(K$160,K63/K$160,0) -> 0 | N63: =VLOOKUP(A63,TB!TB,4,FALSE)*-1 -> 565.2 | O63: =IF(N$160,N63/N$160,0) -> 0.00025643435
A64: 4135601 | C64: Road Parts-Other - Canton | E64: =VLOOKUP(A64,TB!TB1_1,5,FALSE)*-1 -> 31584.85 | F64: =IF(E$160,E64/E$160,0) -> 0.010676815 | H64: =VLOOKUP(A64,TB!TB,5,FALSE)*-1 -> 40289.65 | I64: =IF(H$160,H64/H$160,0) -> 0.018279636 | K64: =VLOOKUP(A64,TB!TB1_1,4,FALSE)*-1 -> 31584.85 | L64: =IF(K$160,K64/K$160,0) -> 0.010676815 | N64: =VLOOKUP(A64,TB!TB,4,FALSE)*-1 -> 40289.65 | O64: =IF(N$160,N64/N$160,0) -> 0.018279636
A65: 4135602 | C65: Road Parts-Other - Cleveland | E65: =VLOOKUP(A65,TB!TB1_1,5,FALSE)*-1 -> 3812.21 | F65: =IF(E$160,E65/E$160,0) -> 0.0012886641 | H65: =VLOOKUP(A65,TB!TB,5,FALSE)*-1 -> 7526.35 | I65: =IF(H$160,H65/H$160,0) -> 0.0034147464 | K65: =VLOOKUP(A65,TB!TB1_1,4,FALSE)*-1 -> 3812.21 | L65: =IF(K$160,K65/K$160,0) -> 0.0012886641 | N65: =VLOOKUP(A65,TB!TB,4,FALSE)*-1 -> 7526.35 | O65: =IF(N$160,N65/N$160,0) -> 0.0034147464
A66: 4136601 | C66: P M -Linde Parts - Canton | E66: =VLOOKUP(A66,TB!TB1_1,5,FALSE)*-1 -> 6354.38 | F66: =IF(E$160,E66/E$160,0) -> 0.002148009 | H66: =VLOOKUP(A66,TB!TB,5,FALSE)*-1 -> 14301.48 | I66: =IF(H$160,H66/H$160,0) -> 0.0064886602 | K66: =VLOOKUP(A66,TB!TB1_1,4,FALSE)*-1 -> 6354.38 | L66: =IF(K$160,K66/K$160,0) -> 0.002148009 | N66: =VLOOKUP(A66,TB!TB,4,FALSE)*-1 -> 14301.48 | O66: =IF(N$160,N66/N$160,0) -> 0.0064886602
...

Sheet Consolidated Expense Statement
A1: Industrial Parts + Service Company
A2: Consolidated Expense Statement
A3: =DATEVALUE(TB!A3&"/"&TB!A4) -> 46023
A4: Description | C4: YTD | F4: MTD | I4: YTD | L4: MTD
A5: Revenue | C5: =TB!A4 -> 2026 | D5: % of Sales | F5: =TB!A4 -> 2026 | G5: % of Sales | I5: =TB!O4 -> 2025 | J5: % of Sales | L5: =TB!O4 -> 2025 | M5: % of Sales
A7: Total Sales | C7: ='Combined Detail P and L'!N160 -> 2204072.9 | D7: =C7/C$7 -> 1 | F7: ='Combined Detail P and L'!H160 -> 2204072.9 | G7: =F7/F$7 -> 1 | I7: ='Combined Detail P and L'!K160 -> 2958265 | J7: =IF(I7,I7/I$7,0) -> 1 | L7: ='Combined Detail P and L'!E160 -> 2958265 | M7: =IF(L7,L7/L$7,0) -> 1
A8: Total GP | C8: ='Combined Detail P and L'!N322 -> 816525.3 | D8: =C8/C$7 -> 0.37046202 | F8: ='Combined Detail P and L'!H322 -> 816525.3 | G8: =F8/F$7 -> 0.37046202 | I8: ='Combined Detail P and L'!K322 -> 757718.3 | J8: =IF(I8,I8/I$7,0) -> 0.25613604 | L8: ='Combined Detail P and L'!E322 -> 757718.3 | M8: =IF(L8,L8/L$7,0) -> 0.25613604
A10: Supervisory | C10: =SUM('Combined Detail P and L'!N326:N339) -> 57023.88 | D10: =C10/C$7 -> 0.025872048 | F10: =SUM('Combined Detail P and L'!H326:H339) -> 57023.88 | G10: =F10/F$7 -> 0.025872048 | I10: =SUM('Combined Detail P and L'!K326:K339) -> 27960 | J10: =IF(I10,I10/I$7,0) -> 0.0094514858 | L10: =SUM('Combined Detail P and L'!E326:E339) -> 27960 | M10: =IF(L10,L10/L$7,0) -> 0.0094514858
A11: Salesmen Salaries | C11: =SUM('Combined Detail P and L'!N340:N346) -> 135811.9 | D11: =C11/C$7 -> 0.061618606 | F11: =SUM('Combined Detail P and L'!H340:H346) -> 135811.9 | G11: =F11/F$7 -> 0.061618606 | I11: =SUM('Combined Detail P and L'!K340:K346) -> 119679.81 | J11: =IF(I11,I11/I$7,0) -> 0.040456081 | L11: =SUM('Combined Detail P and L'!E340:E346) -> 119679.81 | M11: =IF(L11,L11/L$7,0) -> 0.040456081
A12: Support Salaries | C12: =SUM('Combined Detail P and L'!N347:N360) -> 51729.63 | D12: =C12/C$7 -> 0.023470018 | F12: =SUM('Combined Detail P and L'!H347:H360) -> 51729.63 | G12: =F12/F$7 -> 0.023470018 | I12: =SUM('Combined Detail P and L'!K347:K360) -> 46937.65 | J12: =IF(I12,I12/I$7,0) -> 0.015866614 | L12: =SUM('Combined Detail P and L'!E347:E360) -> 46937.65 | M12: =IF(L12,L12/L$7,0) -> 0.015866614
A13: Commissions | C13: =SUM('Combined Detail P and L'!N361:N385) -> 1047.78 | D13: =C13/C$7 -> 0.00047538355 | F13: =SUM('Combined Detail P and L'!H361:H385) -> 1047.78 | G13: =F13/F$7 -> 0.00047538355 | I13: =SUM('Combined Detail P and L'!K361:K385) -> 101604.82 | J13: =IF(I13,I13/I$7,0) -> 0.034346084 | L13: =SUM('Combined Detail P and L'!E361:E385) -> 101604.82 | M13: =IF(L13,L13/L$7,0) -> 0.034346084
A14: Payroll Taxes | C14: =SUM('Combined Detail P and L'!N386:N399) -> 54392.76 | D14: =C14/C$7 -> 0.024678295 | F14: =SUM('Combined Detail P and L'!H386:H399) -> 54392.76 | G14: =F14/F$7 -> 0.024678295 | I14: =SUM('Combined Detail P and L'!K386:K399) -> 45905.48 | J14: =IF(I14,I14/I$7,0) -> 0.015517704 | L14: =SUM('Combined Detail P and L'!E386:E399) -> 45905.48 | M14: =IF(L14,L14/L$7,0) -> 0.015517704
A15: Employee Exp 100% | C15: =SUM('Combined Detail P and L'!N400:N409) -> 2312.36 | D15: =C15/C$7 -> 0.0010491305 | F15: =SUM('Combined Detail P and L'!H400:H409) -> 2312.36 | G15: =F15/F$7 -> 0.0010491305 | I15: =SUM('Combined Detail P and L'!K400:K409) -> 577.5 | J15: =IF(I15,I15/I$7,0) -> 0.00019521577 | L15: =SUM('Combined Detail P and L'!E400:E409) -> 577.5 | M15: =IF(L15,L15/L$7,0) -> 0.00019521577
A16: Employee Exp 50% | C16: =SUM('Combined Detail P and L'!N410:N419) -> 1999.33 | D16: =C16/C$7 -> 0.00090710702 | F16: =SUM('Combined Detail P and L'!H410:H419) -> 1999.33 | G16: =F16/F$7 -> 0.00090710702 | I16: =SUM('Combined Detail P and L'!K410:K419) -> 893.65 | J16: =IF(I16,I16/I$7,0) -> 0.00030208585 | L16: =SUM('Combined Detail P and L'!E410:E419) -> 893.65 | M16: =IF(L16,L16/L$7,0) -> 0.00030208585
A17: Vehicle Repair & Maint | C17: =SUM('Combined Detail P and L'!N420:N429) -> 19624.32 | D17: =C17/C$7 -> 0.008903662 | F17: =SUM('Combined Detail P and L'!H420:H429) -> 19624.32 | G17: =F17/F$7 -> 0.008903662 | I17: =SUM('Combined Detail P and L'!K420:K429) -> 16265.34 | J17: =IF(I17,I17/I$7,0) -> 0.00549827 | L17: =SUM('Combined Detail P and L'!E420:E429) -> 16265.34 | M17: =IF(L17,L17/L$7,0) -> 0.00549827
A18: Rent | C18: =SUM('Combined Detail P and L'!N430:N443) -> 36800 | D18: =C18/C$7 -> 0.016696363 | F18: =SUM('Combined Detail P and L'!H430:H443) -> 36800 | G18: =F18/F$7 -> 0.016696363 | I18: =SUM('Combined Detail P and L'!K430:K443) -> 18064.75 | J18: =IF(I18,I18/I$7,0) -> 0.0061065353 | L18: =SUM('Combined Detail P and L'!E430:E443) -> 18064.75 | M18: =IF(L18,L18/L$7,0) -> 0.0061065353
A19: Utilities | C19: =SUM('Combined Detail P and L'!N444:N445) -> 8562.44 | D19: =C19/C$7 -> 0.0038848262 | F19: =SUM('Combined Detail P and L'!H444:H445) -> 8562.44 | G19: =F19/F$7 -> 0.0038848262 | I19: =SUM('Combined Detail P and L'!H444:K445) -> 15484.574 | J19: =IF(I19,I19/I$7,0) -> 0.005234343 | L19: =SUM('Combined Detail P and L'!E444:E445) -> 6922.13 | M19: =IF(L19,L19/L$7,0) -> 0.0023399289
A20: Building Maintenance | C20: =SUM('Combined Detail P and L'!N446:N447) -> 3372.83 | D20: =C20/C$7 -> 0.0015302715 | F20: =SUM('Combined Detail P and L'!H446:H447) -> 3372.83 | G20: =F20/F$7 -> 0.0015302715 | I20: =SUM('Combined Detail P and L'!K446:K447) -> 15834.76 | J20: =IF(I20,I20/I$7,0) -> 0.0053527185 | L20: =SUM('Combined Detail P and L'!E446:E447) -> 15834.76 | M20: =IF(L20,L20/L$7,0) -> 0.0053527185
A21: Office Supplies | C21: =SUM('Combined Detail P and L'!N448:N461) -> 13475.4 | D21: =C21/C$7 -> 0.0061138631 | F21: =SUM('Combined Detail P and L'!H448:H461) -> 13475.4 | G21: =F21/F$7 -> 0.0061138631 | I21: =SUM('Combined Detail P and L'!K448:K461) -> 2951.99 | J21: =IF(I21,I21/I$7,0) -> 0.00099787881 | L21: =SUM('Combined Detail P and L'!E448:E461) -> 2951.99 | M21: =IF(L21,L21/L$7,0) -> 0.00099787881
A22: Shop Supplies | C22: =SUM('Combined Detail P and L'!N462:N463) -> 6996.54 | D22: =C22/C$7 -> 0.0031743687 | F22: =SUM('Combined Detail P and L'!H462:H463) -> 6996.54 | G22: =F22/F$7 -> 0.0031743687 | I22: =SUM('Combined Detail P and L'!K462:K463) -> 7216.33 | J22: =IF(I22,I22/I$7,0) -> 0.0024393791 | L22: =SUM('Combined Detail P and L'!E462:E463) -> 7216.33 | M22: =IF(L22,L22/L$7,0) -> 0.0024393791
A23: Internal Orders | C23: =SUM('Combined Detail P and L'!N623:N624) -> -67157.89 | D23: =C23/C$7 -> -0.030469904 | F23: =SUM('Combined Detail P and L'!H623:H624) -> -67157.89 | G23: =F23/F$7 -> -0.030469904 | I23: =SUM('Combined Detail P and L'!K623) -> -98430.83 | J23: =IF(I23,I23/I$7,0) -> -0.033273161 | L23: =SUM('Combined Detail P and L'!E623) -> -98430.83 | M23: =IF(L23,L23/L$7,0) -> -0.033273161
A24: Freight | C24: =SUM('Combined Detail P and L'!N464:N469)+E398 -> 3965.2 | D24: =C24/C$7 -> 0.0017990331 | F24: =SUM('Combined Detail P and L'!H466:H469)+H398 -> 3965.2 | G24: =F24/F$7 -> 0.0017990331 | I24: =SUM('Combined Detail P and L'!K466:K469)+K398 -> 6688.68 | J24: =IF(I24,I24/I$7,0) -> 0.0022610144 | L24: =SUM('Combined Detail P and L'!E466:E469)+N398 -> 6688.68 | M24: =IF(L24,L24/L$7,0) -> 0.0022610144
A25: Postage | C25: =SUM('Combined Detail P and L'!N470) -> 0 | D25: =C25/C$7 -> 0 | F25: =SUM('Combined Detail P and L'!H470) -> 0 | G25: =F25/F$7 -> 0 | I25: =SUM('Combined Detail P and L'!K470) -> 63.44 | J25: =IF(I25,I25/I$7,0) -> 2.1445002e-05 | L25: =SUM('Combined Detail P and L'!E470) -> 63.44 | M25: =IF(L25,L25/L$7,0) -> 2.1445002e-05
A26: Communication | C26: =SUM('Combined Detail P and L'!N472:N481) -> 2381.55 | D26: =C26/C$7 -> 0.0010805223 | F26: =SUM('Combined Detail P and L'!H472:H481) -> 2381.55 | G26: =F26/F$7 -> 0.0010805223 | I26: =SUM('Combined Detail P and L'!K472:K481) -> 3220.56 | J26: =IF(I26,I26/I$7,0) -> 0.0010886651 | L26: =SUM('Combined Detail P and L'!E472:E481) -> 3220.56 | M26: =IF(L26,L26/L$7,0) -> 0.0010886651
A27: Legal & Audit | C27: =SUM('Combined Detail P and L'!N482) -> 12015.99 | D27: =C27/C$7 -> 0.0054517208 | F27: =SUM('Combined Detail P and L'!H482) -> 12015.99 | G27: =F27/F$7 -> 0.0054517208 | I27: =SUM('Combined Detail P and L'!K482) -> 21556.4 | J27: =IF(I27,I27/I$7,0) -> 0.0072868386 | L27: =SUM('Combined Detail P and L'!E482) -> 21556.4 | M27: =IF(L27,L27/L$7,0) -> 0.0072868386
A28: Dues & Subscriptions | C28: =SUM('Combined Detail P and L'!N483:N492) -> 22087.26 | D28: =C28/C$7 -> 0.010021111 | F28: =SUM('Combined Detail P and L'!H483:H492) -> 22087.26 | G28: =F28/F$7 -> 0.010021111 | I28: =SUM('Combined Detail P and L'!K483:K492) -> 7071.75 | J28: =IF(I28,I28/I$7,0) -> 0.0023905059 | L28: =SUM('Combined Detail P and L'!E483:E492) -> 7071.75 | M28: =IF(L28,L28/L$7,0) -> 0.0023905059
A29: Product Promotion | C29: =SUM('Combined Detail P and L'!N493:N505) -> 14039.72 | D29: =C29/C$7 -> 0.0063698982 | F29: =SUM('Combined Detail P and L'!H493:H505) -> 14039.72 | G29: =F29/F$7 -> 0.0063698982 | I29: =SUM('Combined Detail P and L'!K493:K505) -> 3442.7 | J29: =IF(I29,I29/I$7,0) -> 0.0011637564 | L29: =SUM('Combined Detail P and L'!E493:E505) -> 3442.7 | M29: =IF(L29,L29/L$7,0) -> 0.0011637564
A30: Training & Education | C30: =SUM('Combined Detail P and L'!N506:N515) -> 0 | D30: =C30/C$7 -> 0 | F30: =SUM('Combined Detail P and L'!H506:H515) -> 0 | G30: =F30/F$7 -> 0 | I30: =SUM('Combined Detail P and L'!K506:K515) -> 0 | J30: =IF(I30,I30/I$7,0) -> 0 | L30: =SUM('Combined Detail P and L'!E506:E515) -> 0 | M30: =IF(L30,L30/L$7,0) -> 0
A31: Consulting Expense | C31: =SUM('Combined Detail P and L'!N516:N525) -> 0 | D31: =C31/C$7 -> 0 | F31: =SUM('Combined Detail P and L'!H516:H525) -> 0 | G31: =F31/F$7 -> 0 | I31: =SUM('Combined Detail P and L'!K516:K525) -> 0 | J31: =IF(I31,I31/I$7,0) -> 0 | L31: =SUM('Combined Detail P and L'!E516:E525) -> 0 | M31: =IF(L31,L31/L$7,0) -> 0
A32: Bad Debt | C32: =SUM('Combined Detail P and L'!N526) -> 0 | D32: =C32/C$7 -> 0 | F32: =SUM('Combined Detail P and L'!H526) -> 0 | G32: =F32/F$7 -> 0 | I32: =SUM('Combined Detail P and L'!K526) -> 0 | J32: =IF(I32,I32/I$7,0) -> 0 | L32: =SUM('Combined Detail P and L'!E526) -> 0 | M32: =IF(L32,L32/L$7,0) -> 0
A33: Contributions | C33: =SUM('Combined Detail P and L'!N527) -> 0 | D33: =C33/C$7 -> 0 | F33: =SUM('Combined Detail P and L'!H527) -> 0 | G33: =F33/F$7 -> 0 | I33: =SUM('Combined Detail P and L'!K527) -> 100 | J33: =IF(I33,I33/I$7,0) -> 3.3803597e-05 | L33: =SUM('Combined Detail P and L'!E527) -> 100 | M33: =IF(L33,L33/L$7,0) -> 3.3803597e-05
A34: Employee Welfare | C34: =SUM('Combined Detail P and L'!N528:N541) -> 7681.06 | D34: =C34/C$7 -> 0.0034849392 | F34: =SUM('Combined Detail P and L'!H528:H541) -> 7681.06 | G34: =F34/F$7 -> 0.0034849392 | I34: =SUM('Combined Detail P and L'!K528:K541) -> 32534.41 | J34: =IF(I34,I34/I$7,0) -> 0.010997801 | L34: =SUM('Combined Detail P and L'!E528:E541) -> 32534.41 | M34: =IF(L34,L34/L$7,0) -> 0.010997801
A35: 401K Contribution | C35: =SUM('Combined Detail P and L'!N542:N555) -> 9276.7 | D35: =C35/C$7 -> 0.0042088898 | F35: =SUM('Combined Detail P and L'!H542:H555) -> 9276.7 | G35: =F35/F$7 -> 0.0042088898 | I35: =SUM('Combined Detail P and L'!K542:K555) -> 8287.56 | J35: =IF(I35,I35/I$7,0) -> 0.0028014934 | L35: =SUM('Combined Detail P and L'!E542:E555) -> 8287.56 | M35: =IF(L35,L35/L$7,0) -> 0.0028014934
A36: Outside Commission | C36: =SUM('Combined Detail P and L'!N556:N559) -> 1900 | D36: =C36/C$7 -> 0.00086204046 | F36: =SUM('Combined Detail P and L'!H556:H559) -> 1900 | G36: =F36/F$7 -> 0.00086204046 | I36: =SUM('Combined Detail P and L'!K556:K559) -> 18504.53 | J36: =IF(I36,I36/I$7,0) -> 0.0062551968 | L36: =SUM('Combined Detail P and L'!E556:E559) -> 18504.53 | M36: =IF(L36,L36/L$7,0) -> 0.0062551968
A37: Personal Property Tax | C37: =SUM('Combined Detail P and L'!N561) -> 0 | D37: =C37/C$7 -> 0 | F37: =SUM('Combined Detail P and L'!H561) -> 0 | G37: =F37/F$7 -> 0 | I37: =SUM('Combined Detail P and L'!K561) -> 0 | J37: =IF(I37,I37/I$7,0) -> 0 | L37: =SUM('Combined Detail P and L'!E561) -> 0 | M37: =IF(L37,L37/L$7,0) -> 0
A38: Insurance | C38: =SUM('Combined Detail P and L'!N562:N575) -> 5319.43 | D38: =C38/C$7 -> 0.0024134547 | F38: =SUM('Combined Detail P and L'!H562:H575) -> 5319.43 | G38: =F38/F$7 -> 0.0024134547 | I38: =SUM('Combined Detail P and L'!K562:K575) -> 9639.9 | J38: =IF(I38,I38/I$7,0) -> 0.003258633 | L38: =SUM('Combined Detail P and L'!E562:E575) -> 9639.9 | M38: =IF(L38,L38/L$7,0) -> 0.003258633
A39: Life Insurance | C39: =SUM('Combined Detail P and L'!N576) -> 0 | D39: =C39/C$7 -> 0 | F39: =SUM('Combined Detail P and L'!H576) -> 0 | G39: =F39/F$7 -> 0 | I39: =SUM('Combined Detail P and L'!K576) -> 0 | J39: =IF(I39,I39/I$7,0) -> 0 | L39: =SUM('Combined Detail P and L'!E576) -> 0 | M39: =IF(L39,L39/L$7,0) -> 0
A40: Interest | C40: =SUM('Combined Detail P and L'!N577:N588) -> 0 | D40: =C40/C$7 -> 0 | F40: =SUM('Combined Detail P and L'!H577:H588) -> 0 | G40: =F40/F$7 -> 0 | I40: =SUM('Combined Detail P and L'!K577:K588) -> 0 | J40: =IF(I40,I40/I$7,0) -> 0 | L40: =SUM('Combined Detail P and L'!E577:E588) -> 0 | M40: =IF(L40,L40/L$7,0) -> 0
A41: Depreciation F & E | C41: =SUM('Combined Detail P and L'!N589:N593) -> 1972.63 | D41: =C41/C$7 -> 0.00089499309 | F41: =SUM('Combined Detail P and L'!H589:H593) -> 1972.63 | G41: =F41/F$7 -> 0.00089499309 | I41: =SUM('Combined Detail P and L'!K589:K593) -> 2606.09 | J41: =IF(I41,I41/I$7,0) -> 0.00088095216 | L41: =SUM('Combined Detail P and L'!E589:E593) -> 2606.09 | M41: =IF(L41,L41/L$7,0) -> 0.00088095216
A42: Depreciation Vehicles | C42: =SUM('Combined Detail P and L'!N594:N595) -> 25984.72 | D42: =C42/C$7 -> 0.01178941 | F42: =SUM('Combined Detail P and L'!H594:H595) -> 25984.72 | G42: =F42/F$7 -> 0.01178941 | I42: =SUM('Combined Detail P and L'!K594:K595) -> 23959.79 | J42: =IF(I42,I42/I$7,0) -> 0.0080992709 | L42: =SUM('Combined Detail P and L'!E594:E595) -> 23959.79 | M42: =IF(L42,L42/L$7,0) -> 0.0080992709
...

Sheet Consolitated Income Statement
A1: Industrial Parts and Service Company
A2: Consolidated Income Statement
A3: =DATEVALUE(TB!A3&"/"&TB!A4) -> 46023
C4: Description | E4: YTD | H4: MTD | K4: YTD | N4: MTD
A5: Account # | C5: Revenue | E5: =TB!A4 -> 2026 | F5: % of Sales | H5: =TB!A4 -> 2026 | I5: % of Sales | K5: =TB!O4 -> 2025 | L5: % of Sales | N5: =TB!O4 -> 2025 | O5: % of Sales
C7: CH Steel Sales Department | E7: ='C H Steel Solutions'!E14 -> 27086.31 | F7: =IF(E$16,E7/E$16,0) -> 0.013260272 | H7: ='C H Steel Solutions'!H14 -> 27086.31 | I7: =IF(H$16,H7/H$16,0) -> 0.013260272 | K7: ='C H Steel Solutions'!K14 -> 1041443.8 | L7: =IF(K$16,K7/K$16,0) -> 0.36806631 | N7: ='C H Steel Solutions'!N14 -> 1041443.8 | O7: =IF(N$16,N7/N$16,0) -> 0.36806631
C8: Dynamic Storage Solutions | E8: ='Dynamic Storage Solutions'!E13 -> 120425.57 | F8: =IF(E$16,E8/E$16,0) -> 0.05895509 | H8: ='Dynamic Storage Solutions'!H13 -> 120425.57 | I8: =IF(H$16,H8/H$16,0) -> 0.05895509 | K8: ='Dynamic Storage Solutions'!K13 -> 279057.17 | L8: =IF(K$16,K8/K$16,0) -> 0.098624182 | N8: ='Dynamic Storage Solutions'!N13 -> 279057.17 | O8: =IF(N$16,N8/N$16,0) -> 0.098624182
C9: AMI Sales Department | E9: ='AMI Sales Department'!E10 -> 457719.63 | F9: =IF(E$16,E9/E$16,0) -> 0.22407951 | H9: ='AMI Sales Department'!H10 -> 457719.63 | I9: =IF(H$16,H9/H$16,0) -> 0.22407951 | K9: ='AMI Sales Department'!K10 -> 356640.7 | L9: =IF(K$16,K9/K$16,0) -> 0.1260437 | N9: ='AMI Sales Department'!N10 -> 356640.7 | O9: =IF(N$16,N9/N$16,0) -> 0.1260437
C10: Canton Sales Department | E10: ='Canton Sales Department'!E14 -> 534513.17 | F10: =IF(E$16,E10/E$16,0) -> 0.26167426 | H10: ='Canton Sales Department'!H14 -> 534513.17 | I10: =IF(H$16,H10/H$16,0) -> 0.26167426 | K10: ='Canton Sales Department'!K14 -> 332165.25 | L10: =IF(K$16,K10/K$16,0) -> 0.1173936 | N10: ='Canton Sales Department'!N14 -> 332165.25 | O10: =IF(N$16,N10/N$16,0) -> 0.1173936
C11: Parts Department | E11: ='Canton Parts Department'!E32 -> 356824.8 | F11: =IF(E$16,E11/E$16,0) -> 0.17468581 | H11: ='Canton Parts Department'!H32 -> 356824.8 | I11: =IF(H$16,H11/H$16,0) -> 0.17468581 | K11: ='Canton Parts Department'!K32 -> 359559.03 | L11: =IF(K$16,K11/K$16,0) -> 0.12707509 | N11: ='Canton Parts Department'!N32 -> 359559.03 | O11: =IF(N$16,N11/N$16,0) -> 0.12707509
C12: Service Department | E12: ='Canton Service Department'!G29 -> 262602.77 | F12: =IF(E$16,E12/E$16,0) -> 0.12855883 | H12: ='Canton Service Department'!J29 -> 262602.77 | I12: =IF(H$16,H12/H$16,0) -> 0.12855883 | K12: ='Canton Service Department'!M29 -> 195151.12 | L12: =IF(K$16,K12/K$16,0) -> 0.068970167 | N12: ='Canton Service Department'!P29 -> 195151.12 | O12: =IF(N$16,N12/N$16,0) -> 0.068970167
C13: Rental Department | E13: ='Canton Rental Department'!E11 -> 254808.52 | F13: =IF(E$16,E13/E$16,0) -> 0.1247431 | H13: ='Canton Rental Department'!H11 -> 254808.52 | I13: =IF(H$16,H13/H$16,0) -> 0.1247431 | K13: ='Canton Rental Department'!K11 -> 248311.77 | L13: =IF(K$16,K13/K$16,0) -> 0.087758165 | N13: ='Canton Rental Department'!N11 -> 248311.77 | O13: =IF(N$16,N13/N$16,0) -> 0.087758165
C14: Used Department | E14: ='Canton Used Department'!E14 -> 28739.73 | F14: =IF(E$16,E14/E$16,0) -> 0.014069714 | H14: ='Canton Used Department'!H14 -> 28739.73 | I14: =IF(H$16,H14/H$16,0) -> 0.014069714 | K14: ='Canton Used Department'!K14 -> 0 | L14: =IF(K$16,K14/K$16,0) -> 0 | N14: ='Canton Used Department'!N14 -> 0 | O14: =IF(N$16,N14/N$16,0) -> 0
C15: G & A Department | E15: ='Administration Department'!E12 -> -54.31 | F15: =IF(E$16,E15/E$16,0) -> -2.65878e-05 | H15: ='Administration Department'!H12 -> -54.31 | I15: =IF(H$16,H15/H$16,0) -> -2.65878e-05 | K15: ='Administration Department'!K12 -> 17171.65 | L15: =IF(K$16,K15/K$16,0) -> 0.006068792 | N15: ='Administration Department'!N12 -> 17171.65 | O15: =IF(N$16,N15/N$16,0) -> 0.006068792
C16: Total Revenue | E16: =SUM(E7:E15) -> 2042666.2 | F16: =IF(E$16,E16/E$16,0) -> 1 | H16: =SUM(H7:H15) -> 2042666.2 | I16: =IF(H$16,H16/H$16,0) -> 1 | K16: =SUM(K7:K15) -> 2829500.5 | L16: =IF(K$16,K16/K$16,0) -> 1 | N16: =SUM(N7:N15) -> 2829500.5 | O16: =IF(N$16,N16/N$16,0) -> 1
C18: Cost of Sales
C19: CH Steel Sales Department | E19: ='C H Steel Solutions'!E27 -> 21686.31 | F19: =IF(E$16,E19/E$16,0) -> 0.010616669 | H19: ='C H Steel Solutions'!H27 -> 21686.31 | I19: =IF(H$16,H19/H$16,0) -> 0.010616669 | K19: ='C H Steel Solutions'!K27 -> 873769.09 | L19: =IF(K$16,K19/K$16,0) -> 0.30880684 | N19: ='C H Steel Solutions'!N27 -> 873769.09 | O19: =IF(N$16,N19/N$16,0) -> 0.30880684
C20: Dynamic Storage Solutions | E20: ='Dynamic Storage Solutions'!E26 -> 107914.8 | F20: =IF(E$16,E20/E$16,0) -> 0.052830365 | H20: ='Dynamic Storage Solutions'!H26 -> 107914.8 | I20: =IF(H$16,H20/H$16,0) -> 0.052830365 | K20: ='Dynamic Storage Solutions'!K26 -> 204313.07 | L20: =IF(K$16,K20/K$16,0) -> 0.072208176 | N20: ='Dynamic Storage Solutions'!N26 -> 204313.07 | O20: =IF(N$16,N20/N$16,0) -> 0.072208176
C21: AMI Sales Department | E21: ='AMI Sales Department'!E23 -> 185106.95 | F21: =IF(E$16,E21/E$16,0) -> 0.090620264 | H21: ='AMI Sales Department'!H23 -> 185106.95 | I21: =IF(H$16,H21/H$16,0) -> 0.090620264 | K21: ='AMI Sales Department'!K23 -> 229722.49 | L21: =IF(K$16,K21/K$16,0) -> 0.081188355 | N21: ='AMI Sales Department'!N23 -> 229722.49 | O21: =IF(N$16,N21/N$16,0) -> 0.081188355
C22: Canton Sales Department | E22: ='Canton Sales Department'!E29 -> 478571.83 | F22: =IF(E$16,E22/E$16,0) -> 0.23428783 | H22: ='Canton Sales Department'!H29 -> 478571.83 | I22: =IF(H$16,H22/H$16,0) -> 0.23428783 | K22: ='Canton Sales Department'!K29 -> 307893.49 | L22: =IF(K$16,K22/K$16,0) -> 0.10881549 | N22: ='Canton Sales Department'!N29 -> 307893.49 | O22: =IF(N$16,N22/N$16,0) -> 0.10881549
C23: Parts Department | E23: ='Canton Parts Department'!E55 -> 227645.64 | F23: =IF(E$16,E23/E$16,0) -> 0.11144535 | H23: ='Canton Parts Department'!H55 -> 227645.64 | I23: =IF(H$16,H23/H$16,0) -> 0.11144535 | K23: ='Canton Parts Department'!K55 -> 238562.87 | L23: =IF(K$16,K23/K$16,0) -> 0.084312716 | N23: ='Canton Parts Department'!N55 -> 238562.87 | O23: =IF(N$16,N23/N$16,0) -> 0.084312716
C24: Service Department | E24: ='Canton Service Department'!G48 -> 75002.87 | F24: =IF(E$16,E24/E$16,0) -> 0.036718124 | H24: ='Canton Service Department'!J48 -> 75002.87 | I24: =IF(H$16,H24/H$16,0) -> 0.036718124 | K24: ='Canton Service Department'!M48 -> 173013.95 | L24: =IF(K$16,K24/K$16,0) -> 0.061146464 | N24: ='Canton Service Department'!P48 -> 173013.95 | O24: =IF(N$16,N24/N$16,0) -> 0.061146464
C25: Rental Department | E25: ='Canton Rental Department'!E20 -> 82096.66 | F25: =IF(E$16,E25/E$16,0) -> 0.040190933 | H25: ='Canton Rental Department'!H20 -> 82096.66 | I25: =IF(H$16,H25/H$16,0) -> 0.040190933 | K25: ='Canton Rental Department'!K20 -> 65581.25 | L25: =IF(K$16,K25/K$16,0) -> 0.023177678 | N25: ='Canton Rental Department'!N20 -> 65581.25 | O25: =IF(N$16,N25/N$16,0) -> 0.023177678
C26: Used Department | E26: ='Canton Used Department'!E27 -> 32449.45 | F26: =IF(E$16,E26/E$16,0) -> 0.015885831 | H26: ='Canton Used Department'!H27 -> 32449.45 | I26: =IF(H$16,H26/H$16,0) -> 0.015885831 | K26: ='Canton Used Department'!K27 -> 3418.2 | L26: =IF(K$16,K26/K$16,0) -> 0.0012080578 | N26: ='Canton Used Department'!N27 -> 3418.2 | O26: =IF(N$16,N26/N$16,0) -> 0.0012080578
C27: Total Cost of Goods Sold | E27: =SUM(E19:E26) -> 1210474.5 | F27: =IF(E$16,E27/E$16,0) -> 0.59259536 | H27: =SUM(H19:H26) -> 1210474.5 | I27: =IF(H$16,H27/H$16,0) -> 0.59259536 | K27: =SUM(K19:K26) -> 2096274.4 | L27: =IF(K$16,K27/K$16,0) -> 0.74086378 | N27: =SUM(N19:N26) -> 2096274.4 | O27: =IF(N$16,N27/N$16,0) -> 0.74086378
C29: Gross Profit | E29: =E16-E27 -> 832191.68 | F29: =IF(E$16,E29/E$16,0) -> 0.40740464 | H29: =H16-H27 -> 832191.68 | I29: =IF(H$16,H29/H$16,0) -> 0.40740464 | K29: =K16-K27 -> 733226.07 | L29: =IF(K$16,K29/K$16,0) -> 0.25913622 | N29: =N16-N27 -> 733226.07 | O29: =IF(N$16,N29/N$16,0) -> 0.25913622
C31: Expenses
C32: CH Steel Sales Department | E32: ='C H Steel Solutions'!E57 -> 31211.04 | F32: =IF(E$16,E32/E$16,0) -> 0.01527956 | H32: ='C H Steel Solutions'!H57 -> 31211.04 | I32: =IF(H$16,H32/H$16,0) -> 0.01527956 | K32: ='C H Steel Solutions'!K57 -> 138346.7 | L32: =IF(K$16,K32/K$16,0) -> 0.04889439 | N32: ='C H Steel Solutions'!N57 -> 138346.7 | O32: =IF(N$16,N32/N$16,0) -> 0.04889439
C33: Dynamic Storage Solutions | E33: ='Dynamic Storage Solutions'!E56 -> 14642.78 | F33: =IF(E$16,E33/E$16,0) -> 0.0071684645 | H33: ='Dynamic Storage Solutions'!H56 -> 14642.78 | I33: =IF(H$16,H33/H$16,0) -> 0.0071684645 | K33: ='Dynamic Storage Solutions'!K56 -> 9594.77 | L33: =IF(K$16,K33/K$16,0) -> 0.0033909766 | N33: ='Dynamic Storage Solutions'!N56 -> 9594.77 | O33: =IF(N$16,N33/N$16,0) -> 0.0033909766
C34: AMI Sales Department | E34: ='AMI Sales Department'!E49 -> 24384.32 | F34: =IF(E$16,E34/E$16,0) -> 0.011937496 | H34: ='AMI Sales Department'!H49 -> 24384.32 | I34: =IF(H$16,H34/H$16,0) -> 0.011937496 | K34: ='AMI Sales Department'!K49 -> 24953.32 | L34: =IF(K$16,K34/K$16,0) -> 0.0088189842 | N34: ='AMI Sales Department'!N49 -> -24953.32 | O34: =IF(N$16,N34/N$16,0) -> -0.0088189842
C35: Canton Sales Department | E35: ='Canton Sales Department'!E56 -> 71330.27 | F35: =IF(E$16,E35/E$16,0) -> 0.034920179 | H35: ='Canton Sales Department'!H56 -> 71330.27 | I35: =IF(H$16,H35/H$16,0) -> 0.034920179 | K35: ='Canton Sales Department'!K56 -> 91058.91 | L35: =IF(K$16,K35/K$16,0) -> 0.032181974 | N35: ='Canton Sales Department'!N56 -> 91058.91 | O35: =IF(N$16,N35/N$16,0) -> 0.032181974
C36: Parts Department | E36: ='Canton Parts Department'!E80 -> 52798.53 | F36: =IF(E$16,E36/E$16,0) -> 0.02584785 | H36: ='Canton Parts Department'!H80 -> 52798.53 | I36: =IF(H$16,H36/H$16,0) -> 0.02584785 | K36: ='Canton Parts Department'!K80 -> 47104.21 | L36: =IF(K$16,K36/K$16,0) -> 0.016647536 | N36: ='Canton Parts Department'!N80 -> 47104.21 | O36: =IF(N$16,N36/N$16,0) -> 0.016647536
C37: Service Department | E37: ='Canton Service Department'!G76 -> 118327.93 | F37: =IF(E$16,E37/E$16,0) -> 0.057928178 | H37: ='Canton Service Department'!J76 -> 118327.93 | I37: =IF(H$16,H37/H$16,0) -> 0.057928178 | K37: ='Canton Service Department'!M76 -> 129197.15 | L37: =IF(K$16,K37/K$16,0) -> 0.045660763 | N37: ='Canton Service Department'!P76 -> 129197.15 | O37: =IF(N$16,N37/N$16,0) -> 0.045660763
C38: Rental Department | E38: ='Canton Rental Department'!E35 -> 7639.73 | F38: =IF(E$16,E38/E$16,0) -> 0.0037400776 | H38: ='Canton Rental Department'!H35 -> 7639.73 | I38: =IF(H$16,H38/H$16,0) -> 0.0037400776 | K38: ='Canton Rental Department'!K35 -> 3630.02 | L38: =IF(K$16,K38/K$16,0) -> 0.001282919 | N38: ='Canton Rental Department'!N35 -> 3630.02 | O38: =IF(N$16,N38/N$16,0) -> 0.001282919
C39: Used Department | E39: ='Canton Used Department'!E45 -> 3001.11 | F39: =IF(E$16,E39/E$16,0) -> 0.0014692122 | H39: ='Canton Used Department'!H45 -> 3001.11 | I39: =IF(H$16,H39/H$16,0) -> 0.0014692122 | K39: ='Canton Used Department'!K45 -> -11606.29 | L39: =IF(K$16,K39/K$16,0) -> -0.0041018866 | N39: ='Canton Used Department'!N45 -> -11606.29 | O39: =IF(N$16,N39/N$16,0) -> -0.0041018866
C40: Total Expenses | E40: =SUM(E32:E39) -> 323335.71 | F40: =IF(E$16,E40/E$16,0) -> 0.15829102 | H40: =SUM(H32:H39) -> 323335.71 | I40: =IF(H$16,H40/H$16,0) -> 0.15829102 | K40: =SUM(K32:K39) -> 432278.79 | L40: =IF(K$16,K40/K$16,0) -> 0.15277566 | N40: =SUM(N32:N39) -> 382372.15 | O40: =IF(N$16,N40/N$16,0) -> 0.13513769
C42: G & A Department | E42: ='Administration Department'!E47 -> 141723.25 | F42: =IF(E$16,E42/E$16,0) -> 0.069381503 | H42: ='Administration Department'!H47 -> 141723.25 | I42: =IF(H$16,H42/H$16,0) -> 0.069381503 | K42: ='Administration Department'!K47 -> 110446.34 | L42: =IF(K$16,K42/K$16,0) -> 0.039033865 | N42: ='Administration Department'!N47 -> 110446.34 | O42: =IF(N$16,N42/N$16,0) -> 0.039033865
C44: Net Income | E44: =E29-(E40+E42) -> 367132.72 | F44: =IF(E$16,E44/E$16,0) -> 0.17973212 | H44: =H29-(H40+H42) -> 367132.72 | I44: =IF(H$16,H44/H$16,0) -> 0.17973212 | K44: =K29-(K40+K42) -> 190500.94 | L44: =IF(K$16,K44/K$16,0) -> 0.067326704 | N44: =N29-(N40+N42) -> 240407.58 | O44: =IF(N$16,N44/N$16,0) -> 0.084964672
E47: =E44-'Combined Detail P and L'!N641 -> -6890.32 | H47: =H44-'Combined Detail P and L'!H641 -> -6890.32 | K47: =K44-'Combined Detail P and L'!K641 -> -21055.6 | N47: =N44-'Combined Detail P and L'!E641 -> 28851.04

Sheet Dynamic Storage Solutions
A1: Industrial Parts and Service Company
A2: Dynamic Storage Solutions Financial
A3: =DATEVALUE(TB!A3&"/"&TB!A4) -> 46023
C4: Description | E4: YTD | H4: MTD | K4: YTD | N4: MTD
A5: Account # | C5: Revenue | E5: =TB!A4 -> 2026 | F5: % of Sales | H5: =TB!A4 -> 2026 | I5: % of Sales | K5: =TB!O4 -> 2025 | L5: % of Sales | N5: =TB!O4 -> 2025 | O5: % of Sales
A6: 4110504 | C6: New Equipment-Linde | E6: =VLOOKUP(A6,TB!TB,4,FALSE)*-1 -> 0 | F6: =IF(E$13,E6/E$13,0) -> 0 | H6: =VLOOKUP(A6,TB!TB,5,FALSE)*-1 -> 0 | I6: =IF(H$13,H6/H$13,0) -> 0 | K6: =VLOOKUP(A6,TB!TB1_1,4,FALSE)*-1 -> 0 | L6: =IF(K$14,K6/K$14,0) -> 0 | N6: =VLOOKUP(A6,TB!TB1_1,5,FALSE)*-1 -> 0 | O6: =IF(N$14,N6/N$14,0) -> 0
