Workbook
Name _new1: #REF!
Name Fax_Page: #REF!
Name GapCover: #REF!
Name Months: 'Composite Preview'!#REF!
Name Months: '[1]Composite Preview'!#REF!
Name Months: [2]Preview!#REF!
Name Months: #REF!
Name Number_of_Months_Included: '[1]Sales, COGS, GP'!$B$7
Name Number_of_Months_Included: 'Sales, COGS, GP'!$B$7
Name NumberofMonths: '[3]Sales, COGS, GP'!$F$5:$F$16
Name NumberofMonthsReported: #REF!
Name NumberofMonthsReporting: '[1]Sales, COGS, GP'!$F$5:$F$16
Name QComp: #REF!
Name TComp: #REF!
Name TechBenefits: 'Composite Preview'!#REF!
Name TechBenefits: '[1]Composite Preview'!#REF!
Name TechBenefits: [2]Preview!#REF!
Name TechBenefits: #REF!

Sheet INSTRUCTIONS
A2: General instructions:
A4: REMINDER: The information contained in this report is confidential. By agreement, this report and all reports associated with the information contained herein may not be shared with any unauthorized parties.
A5: Welcome to the Currie Financial Composite Data Input Template for material handling equipment dealers. Please note that all blue shaded cells are input cells and must be filled in. All other cells may be locked for editing. If you have any questions or need any assistance with the form, please contact Currie Management Consultants, Inc.
A7: Please do not enter "NA" or any other value in the cells other than what is requested. For cells that you are unable to fill in, or that have no value, please leave the cell blank and it will default to the appropriate entry.
A9: All dollar amounts may be entered as whole dollars. All percent values may be entered as whole numbers (for example, 70% may be entered as "70"). In both cases, you may enter the number without adding symbols.
A11: Enter all negative amounts as a negative, using a minus sign before the number.
A13: Once you have completed all worksheets, save and email to reporting@curriemanagement.com
A16: Notes for Currie Tab:
A17: ■Use this space to write any specific explanations of data that may appear to be different than typical reporting. Also use this space to ask questions, or supply feedback and/or suggestions.
A19: Sales, COGS, Gross Profit Tab:
A20: ■Number of Months Included: Please use the dropdown menu and choose the appropriate number. For submissions that contain information for a reporting period greater than one year, please leave the cell blank and write an explanation on the red "NOTES FOR CURRIE" tab.
A22: Most of the remaining information for this sheet will come from your Income Statement. Please enter Sales Revenues in Column A and corresponding COGS in Column B. Gross Profit (Column C) will calculate automatically.
... A197: Thank you! Please call if you need any further assistance!

Sheet NOTES FOR CURRIE
A1: Rental COGs are not tracked short term and long term, all have been entered under short term on expenses sheet Re-Rent sales are included in short term rentals All of our G&A expenses have been reallocated as overhead to the other departments, we will work on splitting those out.

Sheet Sales, COGS, GP
A2: See Instructions tab before entering information. | C2: Please review the Preview tab after all data is entered and enter your name in the blue cell at the top of the Preview.
A3: Dealership Name | B3: Bennett Material Handling | C3: =IF(ISBLANK('Composite Preview'!G1),"NOT REVIEWED",'Composite Preview'!G1) -> NOT REVIEWED
A4: Submitted By | B4: Marissa Lakeman
A5: Date | B5: 10/1/2025
A6: Number of Locations | B6: 1
A7: Number of Months Included | B7: 3
B8: SALES (A) | C8: COGS (B) | D8: GROSS PROFIT (C)
A9: Avg. Monthly Sales & GP | B9: =IF(B7=0,"Please enter Number of Months",B41/B7) -> 1362534.1 | D9: =IF(B7=0,"Please enter Number of Months",D41/B7) -> 444203.9
A10: New Lift Truck Equipment, primary brand | B10: =-'New TB'!O122-'New TB'!O142 -> 1135635 | C10: ='New TB'!O184+'New TB'!O208 -> 940317.64 | D10: =B10-C10 -> 195317.36
A11: New Lift Truck Equipment, other brands | D11: =B11-C11 -> 0
A12: New Allied Equipment | B12: =-'New TB'!O120 -> 13295 | C12: ='New TB'!O182 -> 10848.72 | D12: =B12-C12 -> 2446.28
A13: Other New Equipment | B13: =-SUM('New TB'!O106,'New TB'!O153,'New TB'!O179) -> 14400.18 | C13: =SUM('New TB'!O168,'New TB'!O219,'New TB'!O225,'New TB'!O206,'New TB'!O190,'New TB'!O236) -> 48766.71 | D13: =B13-C13 -> -34366.53
A14: Total New Equipment | B14: =SUM(B10:B13) -> 1163330.2 | C14: =SUM(C10:C13) -> 999933.07 | D14: =B14-C14 -> 163397.11
A15: Operator Training | D15: =B15-C15 -> 0
A16: Used Equipment | B16: =-SUM('New TB'!O107,'New TB'!O130) -> 13063.88 | C16: =SUM('New TB'!O169,'New TB'!O191) -> 2998.98 | D16: =B16-C16 -> 10064.9
A17: E-Commerce | D17: =B17-C17 -> 0
A18: Systems | D18: =B18-C18 -> 0
A19: Batteries | B19: =-SUM('New TB'!O124,'New TB'!O125) -> 36664.5 | C19: =SUM('New TB'!O186,'New TB'!O187) -> 89307.14 | D19: =B19-C19 -> -52642.64
A20: Total Sales Dept. | B20: =SUM(B14:B19) -> 1213058.6 | C20: =SUM(C14:C19) -> 1092239.2 | D20: =B20-C20 -> 120819.37
A21: Short Term Rental Sales | B21: =-SUM('New TB'!O112,'New TB'!O119,'New TB'!O126,'New TB'!O127,'New TB'!O128) -> 1124830.4 | C21: ='Expenses, Miscellaneous'!F37 -> 563827.05 | D21: =B21-C21 -> 561003.31
A22: Long Term Rental Sales | C22: ='Expenses, Miscellaneous'!I37 -> 0 | D22: =B22-C22 -> 0
A23: Re-rent (sub-rent) | C23: ='New TB'!O243 -> 55962 | D23: =B23-C23 -> -55962
A24: Customer Labor | B24: =-SUM('New TB'!O132,'New TB'!O133,'New TB'!O134,'New TB'!O135,'New TB'!O118,'New TB'!O110,'New TB'!O109,'New TB'!O148,'New TB'!O111) -> 723569.22 | C24: =SUM('New TB'!O171:O173,'New TB'!O192:O195,'New TB'!O196,'New TB'!O200,'New TB'!O212:O213,'New TB'!O227) -> 381120.09 | D24: =B24-C24 -> 342449.13
A25: Internal Labor | B25: =-SUM('New TB'!O139,'New TB'!O141) -> 176766.39 | C25: =SUM('New TB'!O205,'New TB'!O202:O203) -> 162180 | D25: =B25-C25 -> 14586.39
A26: Warranty Labor | B26: =-'New TB'!O161-'New TB'!O162-'New TB'!O163-'New TB'!O160 -> 2475 | C26: ='New TB'!O228+'New TB'!O229+'New TB'!O231+'New TB'!O232 -> 5460.37 | D26: =B26-C26 -> -2985.37
A27: Sublet Sales | B27: =-'New TB'!O151 -> 52547.3 | C27: ='New TB'!O217 -> 41346.64 | D27: =B27-C27 -> 11200.66
A28: Other Service Sales | B28: =-'New TB'!O145 -> 0 | C28: ='New TB'!O211 -> 0 | D28: =B28-C28 -> 0
A29: Total Service Sales | B29: =SUM(B24:B28) -> 955357.91 | C29: =SUM(C24:C28) -> 590107.1 | D29: =B29-C29 -> 365250.81
A30: Primary Brand Counter Parts Sales | B30: =-SUM('New TB'!O108,'New TB'!O167,'New TB'!O152) -> 207109.65 | C30: =SUM('New TB'!O170,'New TB'!O218) -> 120580.95 | D30: =B30-C30 -> 86528.7
A31: Other Brand Counter Parts | D31: =B31-C31 -> 0
A32: Primary Brand Repair Order Parts | B32: =-SUM('New TB'!O115,'New TB'!O117,'New TB'!O146) -> 396048.15 | C32: =SUM('New TB'!O177,'New TB'!O201,'New TB'!O213,'New TB'!O178,'New TB'!O180) -> 246666.21 | D32: =B32-C32 -> 149381.94
A33: Other Brand Repair Order Parts | D33: =B33-C33 -> 0
A34: Internal Parts Sales | B34: =-SUM('New TB'!O139,'New TB'!O148) -> 154539.44 | C34: =SUM('New TB'!O204,'New TB'!O214,'New TB'!O240,'New TB'!O241) -> 49607.69 | D34: =B34-C34 -> 104931.75
A35: Warranty Parts Sales | B35: =-'New TB'!O116 -> 9337.68 | C35: ='New TB'!O179 -> 9336.82 | D35: =B35-C35 -> 0.86
A36: E-Commerce Parts Sales | D36: =B36-C36 -> 0
A37: Total Parts Sales | B37: =SUM(B30:B36) -> 767034.92 | C37: =SUM(C30:C36) -> 426191.67 | D37: =B37-C37 -> 340843.25
A38: Trucking Department | B38: ='New TB'!O156 -> 0 | C38: ='Expenses, Miscellaneous'!C38 -> 1718.91 | D38: =B38-C38 -> -1718.91
A40: Total Aftermarket Sales, COGS & GP | B40: =B21+B22+B23+B29+B37+'Expenses, Miscellaneous'!E25 -> 2874543.9 | C40: =C21+C22+C23+C29+C37+'Expenses, Miscellaneous'!E26 -> 1661032.6 | D40: =B40-C40 -> 1213511.2
A41: Total Net Sales & GP | B41: =B20+B38+B40 -> 4087602.4 | C41: =C20+C38+C40 -> 2754990.7 | D41: =B41-C41 -> 1332611.7
A42: Total Company Expenses | B42: ='Expenses, Miscellaneous'!K7 -> 500093.04
...

Sheet Expenses, Miscellaneous
A2: EXPENSE DETAIL
B3: New | C3: Used | D3: *Total Sales Dept. | E3: Parts Dept. | F3: Service Dept. | G3: Short Term Rental | H3: Long Term Rental | I3: Trucking | J3: G&A Dept. | K3: Total
A4: Personnel** | B4: ='New TB'!O315 -> 18634.49 | C4: ='New TB'!O316 -> 1258.46 | D4: =B4+C4 -> 19892.95 | E4: ='New TB'!O318 -> 5145.59 | F4: ='New TB'!O319 -> 5864.04 | G4: ='New TB'!O317 -> 8115.45 | I4: ='New TB'!O320 -> 198.82 | J4: ='New TB'!O321 -> 0 | K4: =SUM(D4:J4) -> 39216.85
A5: Operating | B5: ='New TB'!O323 -> 135756.84 | C5: ='New TB'!O324 -> 9168.16 | D5: =B5+C5 -> 144925 | E5: ='New TB'!O326 -> 37486.92 | F5: ='New TB'!O327 -> 42720.96 | G5: ='New TB'!O325 -> 59123.09 | I5: ='New TB'!O328 -> 1448.51 | J5: ='New TB'!O329 -> 0 | K5: =SUM(D5:J5) -> 285704.48
A6: Occupancy | B6: ='New TB'!O331 -> 83235.5 | C6: ='New TB'!O332 -> 5621.2 | D6: =B6+C6 -> 88856.7 | E6: ='New TB'!O334 -> 22984.05 | F6: ='New TB'!O335 -> 26193.17 | G6: ='New TB'!O333 -> 36249.67 | I6: ='New TB'!O336 -> 888.12 | J6: ='New TB'!O337 -> 0 | K6: =SUM(D6:J6) -> 175171.71
A7: Total | B7: =SUM(B4:B6) -> 237626.83 | C7: =SUM(C4:C6) -> 16047.82 | D7: =B7+C7 -> 253674.65 | E7: =SUM(E4:E6) -> 65616.56 | F7: =SUM(F4:F6) -> 74778.17 | G7: =SUM(G4:G6) -> 103488.21 | H7: =SUM(H4:H6) -> 0 | I7: =SUM(I4:I6) -> 2535.45 | J7: =SUM(J4:J6) -> 0 | K7: =SUM(K4:K6) -> 500093.04
B8: *if you are unable to break out New and Used Expenses, please enter all amounts in the New Column
A9: Personnel Count:
B10: New | C10: Used | D10: Systems | E10: *Total Sales Dept. | F10: Parts Dept. | G10: Service Dept. | H10: Short Term Rental | I10: Long Term Rental | J10: Trucking | K10: G&A Dept. | L10: Total
A11: Managers | B11: 1 | E11: =B11+C11+D11 -> 1 | F11: 0.5 | G11: 1.5 | H11: 1 | L11: =SUM(E11:K11) -> 4
A12: Sales People | B12: 3.5 | C12: 0.5 | E12: =B12+C12+D12 -> 4 | L12: =SUM(E12:K12) -> 4
A13: Technicians / Drivers | F13: 2 | G13: 20 | L13: =SUM(E13:K13) -> 22
A14: Project Engineers | E14: =B14 -> 0 | L14: =SUM(E14:K14) -> 0
A15: Other | E15: =B15+C15+D15 -> 0 | K15: 1.5 | L15: =SUM(E15:K15) -> 1.5
A16: Total | B16: =SUM(B11:B15) -> 4.5 | C16: =SUM(C11:C15) -> 0.5 | D16: =SUM(D11:D15) -> 0 | E16: =B16+C16+D16 -> 5 | F16: =SUM(F11:F15) -> 2.5 | G16: =SUM(G11:G15) -> 21.5 | H16: =SUM(H11:H15) -> 1 | I16: =SUM(I11:I15) -> 0 | J16: =SUM(J11:J15) -> 0 | K16: =SUM(K11:K15) -> 1.5 | L16: =SUM(L11:L15) -> 31.5
B17: *if you are unable to break out New, Used and Systems Personnel Counts, please enter all amounts in the New Column
A19: Miscellaneous Information
A21: Accounts Receivable Aging | D21: Parts Department | G21: Technician Productivity: | K21: Inventory Aging (% over 12 months)
A22: Current | B22: 1590245.8 | D22: Stock Fill Rate % | E22: 0.73 | G22: # of units under full maintenance contract | K22: New Inventory Aging
A23: 31-60 days | B23: 300263.16 | D23: Stock v. NonStock | G23: Customer Labor Rate | K23: Used Inventory Aging
A24: 61-90 days | B24: 196052.85 | D24: Parts Inventory Aging | G24: Avg. Hourly Tech Pay Rate
A25: 91 + days | B25: =54746.94+99356.37+71829.99 -> 225933.3 | D25: Parts Freight Income | E25: =-'New TB'!O131 -> 27320.66 | G25: Total Hours Billed
A26: Total Receivables | B26: =SUM(B22:B25) -> 2312495.1 | D26: Parts Freight Expense | E26: ='New TB'!O192 -> 24944.8 | G26: Productive Hours
G27: Non-Productive Hours | K27: Additional Technician Productivity:
D28: Marketshare Information | G28: Total Hours Paid | I28: =SUM(I26:I27) -> 0 | K28: PM Completion Rate
D29: Sold Units | K29: First Call Completion Rate
D30: Lost Units | K30: Average Response Time (# of hours)
D31: Size of Market
A33: Trucking Department COGS | D33: Short Term Rental COGS | G33: Long Term Rental COGS | K33: Marketing
A34: Maintenance | D34: Depreciation | F34: ='New TB'!O235 -> 477734.08 | G34: Depreciation | K34: Marketing Expense | L34: ='New TB'!O250 -> 917.85
A35: Driver's Salaries | D35: Interest | F35: ='New TB'!O237 -> 62143.97 | G35: Interest
A36: Fuel | D36: Maintenance | F36: =SUM('New TB'!O181,'New TB'!O174,'New TB'!O188,'New TB'!O189,'New TB'!O197) -> 23949 | G36: Maintenance | K36: Service Department
A37: Other costs (See Instructions) | C37: =SUM('New TB'!O175,'New TB'!O198,'New TB'!O222,'New TB'!O224) -> 1718.91 | D37: Total COGS Rental | F37: =SUM(F34:F36) -> 563827.05 | G37: Total COGS Rental | I37: =SUM(I34:I36) -> 0 | K37: Service Calls per day
A38: Total COGS Trucking | C38: =SUM(C34:C37) -> 1718.91 | D38: # of Units in ST Rental Fleet | F38: 440 | G38: # of Units in LT Rental Fleet
D39: Acquisition Cost of ST Fleet | G39: Acquisition Cost of LT Fleet
D40: # of units out on rental (end of month) | F40: =F38*0.8 -> 352

Sheet Balance Sheet
A2: Balance Sheet
A4: ASSETS | D4: LIABILITIES
A5: Current Assets | D5: Current Liabilities
A6: Cash | B6: 919273
A7: Trade Accounts Receivable | B7: 1850797 | D7: A/P Primary Brand | E7: 417887
A8: All Other Accounts Receivable | B8: =8321-16280 -> -7959 | D8: A/P Other
D9: Notes Payable - due within 1 year | E9: 127123
A10: Inventory | D10: Short Term Rental Finance
A11: New Equipment, primary brand | B11: 862817.87 | D11: Used Equipment Financing
A12: New Equipment, other brand | D12: Other Current Liabilities | E12: =716262+19652+48403+21816 -> 806133
A13: New Allied Inventory | B13: 6869.49 | D13: Total Current Liabilities | E13: =SUM(E7:E12) -> 1351143
A14: Other New Equipment
A15: Used Equipment Inventory | B15: 179137.27 | D15: Long Term notes Payable | E15: 6709519
A16: Parts Inventory | B16: 829308.9 | D16: Loans from Stockholders
A17: Battery Inventory | B17: 104791.49 | D17: LT Rental Fleet Financing
A18: Other Inventory | B18: =-4000-7613.6-61378.77 -> -72992.37 | D18: Other Long Term Debt
A19: Total Inventories | B19: =SUM(B11:B18) -> 1909932.6 | D19: Total LT Liabilities | E19: =SUM(E15:E18) -> 6709519
A21: WIP | B21: 154585
A23: Other Current Assets | B23: =48886.08+86948+3671.45+20100 -> 159605.53 | D23: Other Liabilities | E23: =-159450+60853 -> -98597
A24: Total Current Assets | B24: =B6+B7+B8+B19+B23+B21 -> 4986234.2 | D24: Total Liabilities | E24: =E13+E19+E23 -> 7962065
A26: Fixed Assets | D26: Net Worth/Owner Equity
A27: Rental Fleet | B27: 4439391 | D27: Capital Stock | E27: =-#REF!-#REF!-#REF! -> #REF!
A28: Other Long Term or Fixed Assets | B28: =5551769-4439391 -> 1112378 | D28: Retained Earnings | E28: 4233644
A29: Other Assets | B29: 1691206 | D29: Total Net Worth | E29: =SUM(E27:E28) -> #REF!
A30: Total Assets | B30: =B24+B27+B28+B29 -> 12229209 | D30: Total Liabilities & Net Worth | E30: =E24+E29 -> #REF!
E31: =IF(E30=B30,"","Not Balanced") -> #REF!

Sheet Gap Analysis
A1: ='Sales, COGS, GP'!B3 -> Bennett Material Handling
A2: Model Income Statement - Target Results
A4: Sales Mix | B4: Sales Dept. | C4: =IFERROR(B6/P6,"") -> 0.2967653 | D4: Parts | E4: =IFERROR(D6/P6,"") -> 0.1876491 | F4: Service | G4: =IFERROR(F6/P6,"") -> 0.23372085 | H4: Rental | I4: =IFERROR(H6/P6,"") -> 0.27518096 | J4: Rental | K4: =IFERROR(J6/P6,"") -> 0 | L4: Trucking | M4: =IFERROR(L6/P6,"") -> 0 | P4: Model Absorption | Q4: =IFERROR((D8+F8+H8)/P14,"") -> 1.4260218
B5: Sales Dept. | D5: Parts | F5: Service | H5: Short Term Rental | J5: Long Term Rental | L5: Trucking | N5: G&A | P5: Total
A6: Sales | B6: =B23 -> 1213058.6 | D6: =+D23 -> 767034.92 | E6: 1 | F6: =+F23 -> 955357.91 | G6: 1 | H6: =+H23 -> 1124830.4 | I6: 1 | J6: =+J23 -> 0 | K6: 1 | L6: =+L23 -> 0 | M6: 1 | N6: (% of Rental, Service & Parts Revenue) | P6: =P23 -> 4087602.4 | Q6: 1
A8: Gross Profit | B8: =+B25 -> 120819.37 | C8: =+C25 -> 0.099598959 | D8: =E8*D6 -> 306813.97 | E8: =MODELS!$C$4 -> 0.4 | F8: =G8*F6 -> 620982.64 | G8: =MODELS!$D$4 -> 0.65 | H8: =I8*H6 -> 506173.66 | I8: =MODELS!E4 -> 0.45 | J8: =K8*J6 -> 0 | K8: =MODELS!F4 -> 0.2 | L8: =M8*L6 -> 0 | M8: =MODELS!$G$4 -> 0.45 | P8: =B8+D8+F8+H8+J8+L8+('Expenses, Miscellaneous'!E25-'Expenses, Miscellaneous'!E26) -> 1557165.5 | Q8: =P8/P6 -> 0.38094838
C9: 1
A10: Expenses
A11: Personnel | B11: =C11*B$8 -> 60409.685 | C11: =MODELS!B7 -> 0.5 | D11: =E11*D6 -> 76703.492 | E11: =MODELS!C7 -> 0.1 | F11: =G11*F6 -> 191071.58 | G11: =MODELS!D7 -> 0.2 | H11: =I11*H6 -> 112483.04 | I11: =MODELS!E7 -> 0.1 | J11: =K11*J6 -> 0 | K11: =MODELS!F7 -> 0.07 | L11: =M11*L6 -> 0 | N11: =O11*N17 -> 142361.16 | O11: =MODELS!H7 -> 0.05 | P11: =B11+D11+F11+H11+J11+L11+N11 -> 583028.95 | Q11: =P11/P6 -> 0.14263348
A12: Operating | B12: =C12*B$8 -> 30204.842 | C12: =MODELS!B8 -> 0.25 | D12: =E12*D6 -> 23011.048 | E12: =MODELS!C8 -> 0.03 | F12: =G12*F6 -> 95535.791 | G12: =MODELS!D8 -> 0.1 | H12: =I12*H6 -> 33744.911 | I12: =MODELS!E8 -> 0.03 | J12: =K12*J6 -> 0 | K12: =MODELS!F8 -> 0.02 | L12: =M12*L6 -> 0 | N12: =O12*N17 -> 85416.696 | O12: =MODELS!H8 -> 0.03 | P12: =B12+D12+F12+H12+J12+L12+N12 -> 267913.29 | Q12: =P12/P6 -> 0.065542893
A13: Occupancy | B13: =C13*B$8 -> 12081.937 | C13: =MODELS!B9 -> 0.1 | D13: =E13*D6 -> 15340.698 | E13: =MODELS!C9 -> 0.02 | F13: =G13*F6 -> 47767.896 | G13: =MODELS!D9 -> 0.05 | H13: =I13*H6 -> 22496.607 | I13: =MODELS!E9 -> 0.02 | J13: =K13*J6 -> 0 | K13: =MODELS!F9 -> 0.01 | L13: =M13*L6 -> 0 | N13: =O13*N17 -> 56944.464 | O13: =MODELS!H9 -> 0.02 | P13: =B13+D13+F13+H13+J13+L13+N13 -> 154631.6 | Q13: =P13/P6 -> 0.037829414
A14: Total Expenses | B14: =C14*B$8 -> 102696.46 | C14: =MODELS!B10 -> 0.85 | D14: =SUM(D11:D13) -> 115055.24 | E14: =MODELS!C10 -> 0.15 | F14: =SUM(F11:F13) -> 334375.27 | G14: =MODELS!D10 -> 0.35 | H14: =SUM(H11:H13) -> 168724.55 | I14: =MODELS!E10 -> 0.15 | J14: =SUM(J11:J13) -> 0 | K14: =MODELS!F10 -> 0.1 | L14: =SUM(L11:L13) -> 0 | N14: =SUM(N11:N13) -> 284722.32 | O14: =MODELS!H10 -> 0.1 | P14: =SUM(P11:P13) -> 1005573.8 | Q14: =P14/P6 -> 0.24600579
A16: Operating Profit | B16: =B8-B14 -> 18122.905 | C16: =MODELS!B12 -> 0.15 | D16: =D8-D14 -> 191758.73 | E16: =MODELS!C12 -> 0.25 | F16: =F8-F14 -> 286607.37 | G16: =MODELS!D12 -> 0.3 | H16: =H8-H14 -> 337449.11 | I16: =MODELS!E12 -> 0.3 | J16: =J8-J14 -> 0 | K16: =MODELS!F12 -> 0.1 | L16: =L8-L14 -> 0 | N16: =N14*-1 -> -284722.32 | O16: =MODELS!H12 -> -0.1 | P16: =B16+D16+F16+H16+J16+L16+N16 -> 549215.8 | Q16: =P16/P6 -> 0.13436135
N17: =D6+F6+H6 -> 2847223.2
A18: =A1 -> Bennett Material Handling
A19: Actual Income Statement -- Current Reporting Period
A21: Sales Mix | B21: Sales Dept. | C21: =IFERROR('Sales, COGS, GP'!B20/'Sales, COGS, GP'!B41,"") -> 0.2967653 | D21: Parts | E21: =IFERROR('Sales, COGS, GP'!B37/'Sales, COGS, GP'!B41,"") -> 0.1876491 | F21: Service | G21: =IFERROR('Sales, COGS, GP'!B29/'Sales, COGS, GP'!B41,"") -> 0.23372085 | H21: Rental | I21: =IFERROR(('Sales, COGS, GP'!B21+'Sales, COGS, GP'!B23)/'Sales, COGS, GP'!B41,"") -> 0.27518096 | J21: Rental | K21: =IFERROR(('Sales, COGS, GP'!B22)/'Sales, COGS, GP'!D41,"") -> 0 | L21: Trucking | M21: =IFERROR(('Sales, COGS, GP'!B38)/'Sales, COGS, GP'!F41,"") | P21: Actual Absorption | Q21: =IFERROR((D25+F25+H25)/P31,"") -> 2.4218201
B22: Sales Dept. | D22: Parts | F22: Service | H22: Short Term Rental | J22: Long Term Rental | L22: Trucking | N22: G&A | P22: Total
A23: Sales | B23: ='Sales, COGS, GP'!B20 -> 1213058.6 | D23: ='Sales, COGS, GP'!B37 -> 767034.92 | E23: 1 | F23: ='Sales, COGS, GP'!B29 -> 955357.91 | G23: 1 | H23: ='Sales, COGS, GP'!B21+'Sales, COGS, GP'!B23 -> 1124830.4 | I23: 1 | J23: ='Sales, COGS, GP'!B22 -> 0 | K23: 1 | L23: ='Sales, COGS, GP'!B38 -> 0 | M23: 1 | N23: (% of Rental, Service & Parts Revenue) | P23: =B23+D23+F23+H23+J23+L23+'Expenses, Miscellaneous'!E25 -> 4087602.4 | Q23: 1
A25: Gross Profit | B25: ='Sales, COGS, GP'!D20 -> 120819.37 | C25: =+B25/B23 -> 0.099598959 | D25: ='Sales, COGS, GP'!D37 -> 340843.25 | E25: =+D25/D23 -> 0.44436471 | F25: ='Sales, COGS, GP'!D29 -> 365250.81 | G25: =+F25/F23 -> 0.3823183 | H25: ='Sales, COGS, GP'!D21+'Sales, COGS, GP'!D23 -> 505041.31 | I25: =+H25/H23 -> 0.44899331 | J25: ='Sales, COGS, GP'!D22 -> 0 | K25: =+J25/J23 -> #DIV/0! | L25: ='Sales, COGS, GP'!D38 -> -1718.91 | M25: =+L25/L23 -> #DIV/0! | P25: =B25+D25+F25+H25+J25+L25+('Expenses, Miscellaneous'!E25-'Expenses, Miscellaneous'!E26) -> 1332611.7 | Q25: =P25/P23 -> 0.32601304
C26: 1
A27: Expenses
A28: Personnel | B28: ='Expenses, Miscellaneous'!D4 -> 19892.95 | C28: =+B28/B25 -> 0.16465034 | D28: ='Expenses, Miscellaneous'!E4 -> 5145.59 | E28: =+D28/D$23 -> 0.0067084169 | F28: ='Expenses, Miscellaneous'!F4 -> 5864.04 | G28: =+F28/F$23 -> 0.0061380556 | H28: ='Expenses, Miscellaneous'!G4 -> 8115.45 | I28: =+H28/H$23 -> 0.0072148213 | J28: ='Expenses, Miscellaneous'!H4 -> 0 | K28: =+J28/J$23 -> #DIV/0! | L28: ='Expenses, Miscellaneous'!I4 -> 198.82 | M28: =+L28/L$23 -> #DIV/0! | N28: ='Expenses, Miscellaneous'!J4 -> 0 | O28: =N28/SUM(D$23,F$23,H$23) -> 0 | P28: =B28+D28+F28+H28+J28+L28+N28 -> 39216.85 | Q28: =P28/P23 -> 0.009594096
A29: Operating | B29: ='Expenses, Miscellaneous'!D5 -> 144925 | C29: =+B29/B25 -> 1.1995179 | D29: ='Expenses, Miscellaneous'!E5 -> 37486.92 | E29: =+D29/D$23 -> 0.048872508 | F29: ='Expenses, Miscellaneous'!F5 -> 42720.96 | G29: =+F29/F$23 -> 0.044717231 | H29: ='Expenses, Miscellaneous'!G5 -> 59123.09 | I29: =+H29/H$23 -> 0.052561784 | J29: ='Expenses, Miscellaneous'!H5 -> 0 | K29: =+J29/J$23 -> #DIV/0! | L29: ='Expenses, Miscellaneous'!I5 -> 1448.51 | M29: =+L29/L$23 -> #DIV/0! | N29: ='Expenses, Miscellaneous'!J5 -> 0 | O29: =N29/SUM(D$23,F$23,H$23) -> 0 | P29: =B29+D29+F29+H29+J29+L29+N29 -> 285704.48 | Q29: =P29/P23 -> 0.069895369
A30: Occupancy | B30: ='Expenses, Miscellaneous'!D6 -> 88856.7 | C30: =+B30/B25 -> 0.73545078 | D30: ='Expenses, Miscellaneous'!E6 -> 22984.05 | E30: =+D30/D$23 -> 0.029964803 | F30: ='Expenses, Miscellaneous'!F6 -> 26193.17 | G30: =+F30/F$23 -> 0.027417128 | H30: ='Expenses, Miscellaneous'!G6 -> 36249.67 | I30: =+H30/H$23 -> 0.032226788 | J30: ='Expenses, Miscellaneous'!H6 -> 0 | K30: =+J30/J$23 -> #DIV/0! | L30: ='Expenses, Miscellaneous'!I6 -> 888.12 | M30: =+L30/L$23 -> #DIV/0! | N30: ='Expenses, Miscellaneous'!J6 -> 0 | O30: =N30/SUM(D$23,F$23,H$23) -> 0 | P30: =B30+D30+F30+H30+J30+L30+N30 -> 175171.71 | Q30: =P30/P23 -> 0.042854391
A31: Total Expenses | B31: ='Expenses, Miscellaneous'!D7 -> 253674.65 | C31: =+B31/B25 -> 2.099619 | D31: ='Expenses, Miscellaneous'!E7 -> 65616.56 | E31: =+D31/D$23 -> 0.085545727 | F31: ='Expenses, Miscellaneous'!F7 -> 74778.17 | G31: =+F31/F$23 -> 0.078272414 | H31: ='Expenses, Miscellaneous'!G7 -> 103488.21 | I31: =+H31/H$23 -> 0.092003393 | J31: ='Expenses, Miscellaneous'!H7 -> 0 | K31: =+J31/J$23 -> #DIV/0! | L31: ='Expenses, Miscellaneous'!I7 -> 2535.45 | M31: =+L31/L$23 -> #DIV/0! | N31: ='Expenses, Miscellaneous'!J7 -> 0 | O31: =N31/SUM(D$23,F$23,H$23) -> 0 | P31: =B31+D31+F31+H31+J31+L31+N31 -> 500093.04 | Q31: =P31/P23 -> 0.12234386
A33: Operating Profit | B33: =B25-B31 -> -132855.28 | C33: =+B33/B25 -> -1.099619 | D33: =D25-D31 -> 275226.69 | E33: =+D33/D$23 -> 0.35881898 | F33: =F25-F31 -> 290472.64 | G33: =+F33/F$23 -> 0.30404588 | H33: =H25-H31 -> 401553.1 | I33: =+H33/H$23 -> 0.35698992 | J33: =J25-J31 -> 0 | K33: =+J33/J$23 -> #DIV/0! | L33: =L25-L31 -> -4254.36 | M33: =+L33/L$23 -> #DIV/0! | N33: =N31*-1 -> 0 | O33: =N33/SUM(D$23,F$23,H$23) -> 0 | P33: =P25-P31 -> 832518.65 | Q33: =P33/P23 -> 0.20366918
A34: Other Income (Expense) | P34: ='Sales, COGS, GP'!B43 -> -4.7
A35: Interest (Expense) | P35: ='Sales, COGS, GP'!B44 -> -38454.22
A36: F&I (Income) | P36: ='Sales, COGS, GP'!B46 -> 0
A37: Net Profit Before Tax | P37: ='Sales, COGS, GP'!B47 -> 794059.73 | Q37: =IFERROR(+P37/P23,"") -> 0.19426051
N38: =D23+F23+H23 -> 2847223.2
A39: =A1 -> Bennett Material Handling
A40: Gap Analysis (Difference Between Target and Actual Results)
B42: Sales Dept. | D42: Parts | F42: Service | H42: Short Term Rental | J42: Long Term Rental | L42: Trucking | N42: G&A | P42: Total
A44: Gross Profit | D44: =D25-D8 -> 34029.282 | E44: =E25-E8 -> 0.04436471 | F44: =F25-F8 -> -255731.83 | G44: =G25-G8 -> -0.2676817 | H44: =H25-H8 -> -1132.352 | I44: =I25-I8 -> -0.0010066869 | J44: =J25-J8 -> 0 | K44: =K25-K8 -> #DIV/0! | ... M44: =M25-M8 -> #DIV/0! | P44: =P25-P8 -> -224553.81 | Q44: =Q25-Q8 -> -0.054935336
A46: Expenses
A47: Personnel | B47: =B11-B28 -> 40516.735 | C47: =C11-C28 -> 0.33534966 | D47: =D11-D28 -> 71557.902 | E47: =E11-E28 -> 0.093291583 | F47: =F11-F28 -> 185207.54 | G47: =G11-G28 -> 0.19386194 | H47: =H11-H28 -> 104367.59 | I47: =I11-I28 -> 0.092785179 | ... Q47: =Q11-Q28 -> 0.13303938
A48: Operating | B48: =B12-B29 -> -114720.16 | C48: =C12-C29 -> -0.94951792 | D48: =D12-D29 -> -14475.872 | E48: =E12-E29 -> -0.018872508 | F48: =F12-F29 -> 52814.831 | G48: =G12-G29 -> 0.055282769 | H48: =H12-H29 -> -25378.179 | I48: =I12-I29 -> -0.022561784 | ... Q48: =Q12-Q29 -> -0.0043524762
A49: Occupancy | B49: =B13-B30 -> -76774.763 | C49: =C13-C30 -> -0.63545078 | D49: =D13-D30 -> -7643.3516 | E49: =E13-E30 -> -0.0099648026 | F49: =F13-F30 -> 21574.726 | G49: =G13-G30 -> 0.022582872 | H49: =H13-H30 -> -13753.063 | I49: =I13-I30 -> -0.012226788 | ... Q49: =Q13-Q30 -> -0.005024977
...

Sheet Composite Preview
A1: Data Submitted on | B1: ='Sales, COGS, GP'!B5 -> 10/1/2025 | D1: by | F1: Reviewed by:
A2: Total Operation Recap | E2: Sales Department | I2: Sales Department Mix & Productivity
A3: ='Sales, COGS, GP'!A3 -> Dealership Name | B3: ='Sales, COGS, GP'!B3 -> Bennett Material Handling | E3: Dealership Name | F3: =B3 -> Bennett Material Handling | I3: Dealership Name | J3: =B3 -> Bennett Material Handling
A4: ='Sales, COGS, GP'!A7 -> Number of Months Included | B4: ='Sales, COGS, GP'!B7 -> 3 | E4: Number of Months Included | F4: =B4 -> 3 | G4: Model | I4: Number of Months Included | J4: =B4 -> 3 | K4: Model
A6: Average Monthly Sales | B6: ='Sales, COGS, GP'!B9 -> 1362534.1 | E6: Average Monthly Sales | F6: =IFERROR('Sales, COGS, GP'!B20/'Sales, COGS, GP'!B7,"") -> 404352.85 | I6: Sales Mix
I7: New Primary Brand Equipment | J7: =IFERROR('Sales, COGS, GP'!B10/'Sales, COGS, GP'!B$20,"") -> 0.93617492
A8: Model Gross Profit | B8: =IFERROR(('Sales, COGS, GP'!D20+(('Sales, COGS, GP'!B21+'Sales, COGS, GP'!B23)*'Gap Analysis'!I8)+('Sales, COGS, GP'!B22*'Gap Analysis'!K8)+('Sales, COGS, GP'!B29*'Gap Analysis'!G8)+('Sales, COGS, GP'!B37*'Gap Analysis'!E8)+('Sales, COGS, GP'!B38*'Gap Analysis'!M8)+('Expenses, Miscellaneous'!E25-'Expenses, Miscellaneous'!E26))/'Sales, COGS, GP'!B41,"") -> 0.38094838 | E8: Gross Profit | F8: =IFERROR('Sales, COGS, GP'!D20/'Sales, COGS, GP'!B20,"") -> 0.099598959 | I8: New Other Brand Equipment | J8: =IFERROR('Sales, COGS, GP'!B11/'Sales, COGS, GP'!B$20,"") -> 0
A9: Actual Gross Profit | B9: =IFERROR('Sales, COGS, GP'!D41/'Sales, COGS, GP'!B41,"") -> 0.32601304 | I9: New Allied Equipment | J9: =IFERROR('Sales, COGS, GP'!B12/'Sales, COGS, GP'!B$20,"") -> 0.0109599
E10: Expenses (% Of G.P.) | I10: Other New Equipment | J10: =IFERROR('Sales, COGS, GP'!B13/'Sales, COGS, GP'!B$20,"") -> 0.011870969
A11: Expenses (% Of Sales) | E11: Personnel | F11: =IFERROR('Expenses, Miscellaneous'!D4/'Sales, COGS, GP'!D$20,"") -> 0.16465034 | G11: =MODELS!B7 -> 0.5 | I11: Operator Training | J11: =IFERROR('Sales, COGS, GP'!B15/'Sales, COGS, GP'!B$20,"") -> 0
A12: Model Personnel | B12: =IFERROR((('Sales, COGS, GP'!D20*'Gap Analysis'!C11)+(('Sales, COGS, GP'!B21+'Sales, COGS, GP'!B23)*'Gap Analysis'!I11)+('Sales, COGS, GP'!B22*'Gap Analysis'!K11)+('Sales, COGS, GP'!B29*'Gap Analysis'!G11)+('Sales, COGS, GP'!B37*'Gap Analysis'!E11)+('Sales, COGS, GP'!B40*'Gap Analysis'!O11))/'Sales, COGS, GP'!B41,"") -> 0.14296767 | E12: Operating | F12: =IFERROR('Expenses, Miscellaneous'!D5/'Sales, COGS, GP'!D$20,"") -> 1.1995179 | G12: =MODELS!B8 -> 0.25 | I12: Used Equipment | J12: =IFERROR('Sales, COGS, GP'!B16/'Sales, COGS, GP'!B$20,"") -> 0.010769373
A13: Actual Personnel | B13: =IFERROR('Expenses, Miscellaneous'!K4/'Sales, COGS, GP'!B41,"") -> 0.009594096 | E13: Occupancy | F13: =IFERROR('Expenses, Miscellaneous'!D6/'Sales, COGS, GP'!D$20,"") -> 0.73545078 | G13: =MODELS!B9 -> 0.1 | I13: E Commerce | J13: =IFERROR('Sales, COGS, GP'!B17/'Sales, COGS, GP'!B$20,"") -> 0
E14: Total Expenses | F14: =IFERROR('Expenses, Miscellaneous'!D7/'Sales, COGS, GP'!D$20,"") -> 2.099619 | G14: =MODELS!B10 -> 0.85 | I14: Systems | J14: =IFERROR('Sales, COGS, GP'!B18/'Sales, COGS, GP'!B$20,"") -> 0
A15: Model Operating | B15: =IFERROR((('Sales, COGS, GP'!D20*'Gap Analysis'!C12)+(('Sales, COGS, GP'!B21+'Sales, COGS, GP'!B23)*'Gap Analysis'!I12)+('Sales, COGS, GP'!B22*'Gap Analysis'!K12)+('Sales, COGS, GP'!B29*'Gap Analysis'!G12)+('Sales, COGS, GP'!B37*'Gap Analysis'!E12)+('Sales, COGS, GP'!B40*'Gap Analysis'!O12))/'Sales, COGS, GP'!B41,"") -> 0.065743407 | I15: Batteries | J15: =IFERROR('Sales, COGS, GP'!B19/'Sales, COGS, GP'!B$20,"") -> 0.030224839
A16: Actual Operating | B16: =IFERROR('Expenses, Miscellaneous'!K5/'Sales, COGS, GP'!B41,"") -> 0.069895369 | E16: Department Profit | F16: =IFERROR(('Sales, COGS, GP'!D20-'Expenses, Miscellaneous'!D7)/'Sales, COGS, GP'!D20,"") -> -1.099619 | G16: =MODELS!B12 -> 0.15 | I16: Total Sales | J16: =SUM(J7:J15) -> 1
E17: Department Profit $ * | F17: ='Sales, COGS, GP'!D20-'Expenses, Miscellaneous'!D7 -> -132855.28 | G17: ='Gap Analysis'!C16*'Sales, COGS, GP'!D20 -> 18122.905
A18: Model Occupancy | B18: =IFERROR((('Sales, COGS, GP'!D20*'Gap Analysis'!C13)+(('Sales, COGS, GP'!B21+'Sales, COGS, GP'!B23)*'Gap Analysis'!I13)+('Sales, COGS, GP'!B22*'Gap Analysis'!K13)+('Sales, COGS, GP'!B29*'Gap Analysis'!G13)+('Sales, COGS, GP'!B37*'Gap Analysis'!E13)+('Sales, COGS, GP'!B40*'Gap Analysis'!O13))/'Sales, COGS, GP'!B41,"") -> 0.037963089 | I18: Gross Profit
A19: Actual Occupancy | B19: =IFERROR('Expenses, Miscellaneous'!K6/'Sales, COGS, GP'!B41,"") -> 0.042854391 | E19: Inventory Turns | I19: New Primary Brand Equipment | J19: =IFERROR('Sales, COGS, GP'!D10/'Sales, COGS, GP'!B10,"") -> 0.17198956
E20: New Primary Brand Equipment | F20: =IFERROR((('Sales, COGS, GP'!C10/'Sales, COGS, GP'!B7)*12)/'Balance Sheet'!B11,"") -> 4.3592868 | G20: 12 | I20: New Other Brand Equipment | J20: =IFERROR('Sales, COGS, GP'!D11/'Sales, COGS, GP'!B11,"")
A21: Model Total Expense | B21: =IFERROR((('Sales, COGS, GP'!D20*'Gap Analysis'!C14)+(('Sales, COGS, GP'!B21+'Sales, COGS, GP'!B23)*'Gap Analysis'!I14)+('Sales, COGS, GP'!B22*'Gap Analysis'!K14)+('Sales, COGS, GP'!B29*'Gap Analysis'!G14)+('Sales, COGS, GP'!B37*'Gap Analysis'!E14)+('Sales, COGS, GP'!B40*'Gap Analysis'!O14))/'Sales, COGS, GP'!B41,"") -> 0.24667416 | E21: New Other Brand Equipment | F21: =IFERROR((('Sales, COGS, GP'!C11/'Sales, COGS, GP'!B7)*12)/'Balance Sheet'!B12,"") | G21: 12 | I21: New Allied Equipment | J21: =IFERROR('Sales, COGS, GP'!D12/'Sales, COGS, GP'!B12,"") -> 0.184
A22: Actual Total Expense | B22: =IFERROR('Expenses, Miscellaneous'!K7/'Sales, COGS, GP'!B41,"") -> 0.12234386 | E22: New Allied Equipment | F22: =IFERROR((('Sales, COGS, GP'!C12/'Sales, COGS, GP'!B7)*12)/'Balance Sheet'!B13,"") -> 6.3170454 | I22: Other New Equipment | J22: =IFERROR('Sales, COGS, GP'!D13/'Sales, COGS, GP'!B13,"") -> -2.3865348
E23: Used Equipment | F23: =IFERROR((('Sales, COGS, GP'!C16/'Sales, COGS, GP'!B7)*12)/'Balance Sheet'!B15,"") -> 0.066964959 | G23: 6 | I23: Operator Training | J23: =IFERROR('Sales, COGS, GP'!D15/'Sales, COGS, GP'!B15,"")
A24: Model Department Profit | B24: =IFERROR((('Sales, COGS, GP'!D20*'Gap Analysis'!C16)+(('Sales, COGS, GP'!B21+'Sales, COGS, GP'!B23)*'Gap Analysis'!I16)+('Sales, COGS, GP'!B22*'Gap Analysis'!K16)+('Sales, COGS, GP'!B29*'Gap Analysis'!G16)+('Sales, COGS, GP'!B37*'Gap Analysis'!E16)+('Sales, COGS, GP'!B40*'Gap Analysis'!O16)+('Expenses, Miscellaneous'!E25-'Expenses, Miscellaneous'!E26))/'Sales, COGS, GP'!B41,"") -> 0.13427421 | I24: Used Equipment | J24: =IFERROR('Sales, COGS, GP'!D16/'Sales, COGS, GP'!B16,"") -> 0.77043727
A25: Actual Department Profit | B25: =IFERROR((('Sales, COGS, GP'!D41-'Sales, COGS, GP'!B42)/'Sales, COGS, GP'!B41),"") -> 0.20366918 | E25: Inventory Aging | I25: E Commerce | J25: =IFERROR('Sales, COGS, GP'!D17/'Sales, COGS, GP'!B17,"")
E26: New Inventory Aging | F26: ='Expenses, Miscellaneous'!L12 -> 4 | I26: Systems | J26: =IFERROR('Sales, COGS, GP'!D18/'Sales, COGS, GP'!B18,"")
A27: Other Income/Expenses | B27: =IFERROR('Sales, COGS, GP'!B43/'Sales, COGS, GP'!B41,"") -> -1.1498183e-06 | E27: Used Inventory Aging | F27: ='Expenses, Miscellaneous'!L13 -> 22 | I27: Batteries | J27: =IFERROR('Sales, COGS, GP'!D19/'Sales, COGS, GP'!B19,"") -> -1.4357932
A28: Interest Expense | B28: =IFERROR('Sales, COGS, GP'!B44/'Sales, COGS, GP'!B41,"") -> -0.0094075245 | I28: Total Gross Profit | J28: =IFERROR('Sales, COGS, GP'!D20/'Sales, COGS, GP'!B20,"") -> 0.099598959
A29: Actual Net Before Tax | B29: =IFERROR('Sales, COGS, GP'!B47/'Sales, COGS, GP'!B41,"") -> 0.19426051 | E29: Marketshare Info
E30: Participation | F30: =IFERROR(('Expenses, Miscellaneous'!E29+'Expenses, Miscellaneous'!E30)/'Expenses, Miscellaneous'!E31,"") | G30: 0.66 | I30: Total Sales Dept. Employees | J30: ='Expenses, Miscellaneous'!E16 -> 5
A31: Avg. Mo. Sales $ Per Emp. | B31: =IFERROR('Sales, COGS, GP'!B9/'Expenses, Miscellaneous'!L16,"") -> 43255.052 | E31: Close Rate | F31: =IFERROR('Expenses, Miscellaneous'!E29/('Expenses, Miscellaneous'!E29+'Expenses, Miscellaneous'!E30),"") | G31: 0.5 | I31: Mo. Sls $ / Dept. Emp. | J31: =IFERROR(('Sales, COGS, GP'!B20/'Sales, COGS, GP'!B7)/'Expenses, Miscellaneous'!E16,"") -> 80870.571
A32: Avg. Mo. GP $ Per Emp. | B32: =IFERROR('Sales, COGS, GP'!D9/'Expenses, Miscellaneous'!L16,"") -> 14101.711 | E32: Marketshare | F32: =IFERROR('Expenses, Miscellaneous'!E29/'Expenses, Miscellaneous'!E31,"") | G32: 0.33 | I32: Mo. GP $ / Dept. Emp. | J32: =IFERROR(('Sales, COGS, GP'!D20/'Sales, COGS, GP'!B7)/'Expenses, Miscellaneous'!E16,"") -> 8054.6247
E33: *Shaded areas will not appear on the final composite
I34: Sales Rep to Support Ratio | J34: =IFERROR('Expenses, Miscellaneous'!E12/('Expenses, Miscellaneous'!E11+'Expenses, Miscellaneous'!E14+'Expenses, Miscellaneous'!E15), "") -> 4 | K34: 3
I35: Total Sales People | J35: ='Expenses, Miscellaneous'!E12 -> 4
I37: Mo. Sls $/Salesperson | J37: =IFERROR(('Sales, COGS, GP'!B20/'Sales, COGS, GP'!B7)/'Expenses, Miscellaneous'!E12,"") -> 101088.21
A38: Financial Composite Preview prepared by Currie Management Consultants, Inc. for | I38: Mo. GP $/Salesperson | J38: =IFERROR(('Sales, COGS, GP'!D20/'Sales, COGS, GP'!B7)/'Expenses, Miscellaneous'!E12,"") -> 10068.281 | K38: 20000
A39: ='Sales, COGS, GP'!B3 -> Bennett Material Handling
A40: Parts Department | E40: Parts Department Mix & Productivity | I40: Service Department
A41: Dealership Name | B41: =B3 -> Bennett Material Handling | E41: Dealership Name | F41: =B3 -> Bennett Material Handling | I41: Dealership Name | J41: =B3 -> Bennett Material Handling
A42: Number of Months Included | B42: =B4 -> 3 | C42: Model | E42: Number of Months Included | F42: =B4 -> 3 | G42: Model | I42: Number of Months Included | J42: =B4 -> 3 | K42: Model
...

Sheet MODELS
A1: Currie Financial Model Lift Truck Dealer
B3: Sales | C3: Parts | D3: Service | E3: Short T Rental | F3: Long T Rental | G3: Trucking | H3: G & A
A4: Gross Profit | B4: =+B22 -> 0 | C4: 0.4 | D4: 0.65 | E4: 0.45 | F4: 0.2 | G4: 0.45
B5: 1
A6: Expenses
A7: Personnel | B7: 0.5 | C7: 0.1 | D7: 0.2 | E7: 0.1 | F7: 0.07 | H7: 0.05
A8: Operating | B8: 0.25 | C8: 0.03 | D8: 0.1 | E8: 0.03 | F8: 0.02 | H8: 0.03
A9: Occupancy | B9: 0.1 | C9: 0.02 | D9: 0.05 | E9: 0.02 | F9: 0.01 | H9: 0.02
A10: Total Expenses | B10: =SUM(B7:B9) -> 0.85 | C10: =SUM(C7:C9) -> 0.15 | D10: =SUM(D7:D9) -> 0.35 | E10: =SUM(E7:E9) -> 0.15 | F10: =SUM(F7:F9) -> 0.1 | H10: =SUM(H7:H9) -> 0.1
A12: Operating Profit | B12: =B5-B10 -> 0.15 | C12: =C4-C10 -> 0.25 | D12: =D4-D10 -> 0.3 | E12: =E4-E10 -> 0.3 | F12: =F4-F10 -> 0.1 | H12: =H10*-1 -> -0.1

Sheet New TB
A1: Acct | B1: Description | C1: January | D1: February | E1: March | F1: April | G1: May | H1: June | I1: July | J1: August | K1: September | L1: October | M1: November | N1: December | O1: YTD
A2: 110000 | B2: CASH - OPERATING ACCOUNT | C2: 32229.97 | D2: 354138.03 | E2: 852302.19 | O2: =SUM(C2:N2) -> 1238670.2
A3: 111000 | B3: CASH - PAYROLL ACCOUNT | C3: -105857.3 | D3: 0 | E3: 87.5 | O3: =SUM(C3:N3) -> -105769.8
A4: 112000 | B4: CASH - SELECT ACCOUNT | C4: 0 | D4: 0 | E4: 0 | O4: =SUM(C4:N4) -> 0
A5: 113000 | B5: CASH - PETTY CASH | C5: 0 | D5: 0 | E5: 0 | O5: =SUM(C5:N5) -> 0
A6: 114000 | B6: CASH - S/T INVESTMENTS | C6: 48.32 | D6: -599956.22 | E6: 48.6 | O6: =SUM(C6:N6) -> -599859.3
A7: 115000 | B7: CASH - COLLATERAL ACCOUNT | C7: 0 | D7: 0 | E7: 0 | O7: =SUM(C7:N7) -> 0
A8: 120000 | B8: ACCOUNTS RECEIVABLE - TRADE | C8: -41577.86 | D8: 221196.65 | E8: -688509.48 | O8: =SUM(C8:N8) -> -508890.69
A9: 121000 | B9: ACCOUNTS RECEIVABLE - WARRANTY | C9: -4701.86 | D9: 125 | E9: 0 | O9: =SUM(C9:N9) -> -4576.86
A10: 121100 | B10: UNREALIZED WARRANTY INCOME | C10: 0 | D10: 0 | E10: 0 | O10: =SUM(C10:N10) -> 0
A11: 122000 | B11: ACCOUNTS RECEIVABLE - OTHER | C11: 0 | D11: 0 | E11: 0 | O11: =SUM(C11:N11) -> 0
A12: 123000 | B12: ACCOUNTS RECEIVABLE - NOTES | C12: 0 | D12: 0 | E12: 0 | O12: =SUM(C12:N12) -> 0
A13: 124000 | B13: COMMISSIONS RECEIVABLE | C13: 0 | D13: 0 | E13: 0 | O13: =SUM(C13:N13) -> 0
... A311: 999999 | B311: ERROR ACCOUNT | C311: 60 | D311: -60 | E311: 0 | O311: =SUM(C311:N311) -> 0
O312: =SUM(C312:N312) -> 0
O313: =SUM(C313:N313) -> 0
B314: Personnel | C314: =SUM(C255,C258,C264,C268,C270,C273,C274,C277,C278,C279,C283,C284,C310) -> -26880.91 | D314: =SUM(D255,D258,D264,D268,D270,D273,D274,D277,D278,D279,D283,D284,D310) -> -32471.58 | E314: =SUM(E255,E258,E264,E268,E270,E273,E274,E277,E278,E279,E283,E284,E310) -> 98568.96 | F314: =SUM(F255,F258,F264,F268,F270,F273,F274,F277,F278,F279,F283,F284,F310) -> 0 | G314: =SUM(G255,G258,G264,G268,G270,G273,G274,G277,G278,G279,G283,G284,G310) -> 0 | H314: =SUM(H255,H258,H264,H268,H270,H273,H274,H277,H278,H279,H283,H284,H310) -> 0 | I314: =SUM(I255,I258,I264,I268,I270,I273,I274,I277,I278,I279,I283,I284,I310) -> 0 | J314: =SUM(J255,J258,J264,J268,J270,J273,J274,J277,J278,J279,J283,J284,J310) -> 0 | ... N314: =SUM(N255,N258,N264,N268,N270,N273,N274,N277,N278,N279,N283,N284,N310) -> 0 | O314: =SUM(C314:N314) -> 39216.47
B315: New | C315: =ROUND(C314*47.517%,2) -> -12773 | D315: =ROUND(D314*47.517%,2) -> -15429.52 | E315: =ROUND(E314*47.517%,2) -> 46837.01 | F315: =ROUND(F314*47.517%,2) -> 0 | G315: =ROUND(G314*47.517%,2) -> 0 | H315: =ROUND(H314*47.517%,2) -> 0 | I315: =ROUND(I314*47.517%,2) -> 0 | J315: =ROUND(J314*47.517%,2) -> 0 | ... N315: =ROUND(N314*47.517%,2) -> 0 | O315: =SUM(C315:N315) -> 18634.49
B316: Used | C316: =ROUND(C314*3.209%,2) -> -862.61 | D316: =ROUND(D314*3.209%,2) -> -1042.01 | E316: =ROUND(E314*3.209%,2) -> 3163.08 | F316: =ROUND(F314*3.209%,2) -> 0 | G316: =ROUND(G314*3.209%,2) -> 0 | H316: =ROUND(H314*3.209%,2) -> 0 | I316: =ROUND(I314*3.209%,2) -> 0 | J316: =ROUND(J314*3.209%,2) -> 0 | ... N316: =ROUND(N314*3.209%,2) -> 0 | O316: =SUM(C316:N316) -> 1258.46
B317: Rental | C317: =ROUND(C314*20.694%,2) -> -5562.74 | D317: =ROUND(D314*20.694%,2) -> -6719.67 | E317: =ROUND(E314*20.694%,2) -> 20397.86 | F317: =ROUND(F314*20.694%,2) -> 0 | G317: =ROUND(G314*20.694%,2) -> 0 | H317: =ROUND(H314*20.694%,2) -> 0 | I317: =ROUND(I314*20.694%,2) -> 0 | J317: =ROUND(J314*20.694%,2) -> 0 | ... N317: =ROUND(N314*20.694%,2) -> 0 | O317: =SUM(C317:N317) -> 8115.45
B318: Parts | C318: =ROUND(C314*13.121%,2) -> -3527.04 | D318: =ROUND(D314*13.121%,2) -> -4260.6 | E318: =ROUND(E314*13.121%,2) -> 12933.23 | F318: =ROUND(F314*13.121%,2) -> 0 | G318: =ROUND(G314*13.121%,2) -> 0 | H318: =ROUND(H314*13.121%,2) -> 0 | I318: =ROUND(I314*13.121%,2) -> 0 | J318: =ROUND(J314*13.121%,2) -> 0 | ... N318: =ROUND(N314*13.121%,2) -> 0 | O318: =SUM(C318:N318) -> 5145.59
B319: Service | C319: =ROUND(C314*14.953%,2) -> -4019.5 | D319: =ROUND(D314*14.953%,2) -> -4855.48 | E319: =ROUND(E314*14.953%,2) -> 14739.02 | F319: =ROUND(F314*14.953%,2) -> 0 | G319: =ROUND(G314*14.953%,2) -> 0 | H319: =ROUND(H314*14.953%,2) -> 0 | I319: =ROUND(I314*14.953%,2) -> 0 | J319: =ROUND(J314*14.953%,2) -> 0 | ... N319: =ROUND(N314*14.953%,2) -> 0 | O319: =SUM(C319:N319) -> 5864.04
B320: Transport | C320: =ROUND(C314*0.507%,2) -> -136.29 | D320: =ROUND(D314*0.507%,2) -> -164.63 | E320: =ROUND(E314*0.507%,2) -> 499.74 | F320: =ROUND(F314*0.507%,2) -> 0 | G320: =ROUND(G314*0.507%,2) -> 0 | H320: =ROUND(H314*0.507%,2) -> 0 | I320: =ROUND(I314*0.507%,2) -> 0 | J320: =ROUND(J314*0.507%,2) -> 0 | ... N320: =ROUND(N314*0.507%,2) -> 0 | O320: =SUM(C320:N320) -> 198.82
B321: Admin | O321: =SUM(C321:N321) -> 0
B322: Operating | C322: =SUM(C251,C254,C256,C257,C263,C265,C266,C269,C272,C275,C276,C280,C285:C292,C295:C300) -> 116923.38 | D322: =SUM(D251,D254,D256,D257,D263,D265,D266,D269,D272,D275,D276,D280,D285:D292,D295:D300) -> 71273.43 | E322: =SUM(E251,E254,E256,E257,E263,E265,E266,E269,E272,E275,E276,E280,E285:E292,E295:E300) -> 97504.81 | F322: =SUM(F251,F254,F256,F257,F263,F265,F266,F269,F272,F275,F276,F280,F285:F292,F295:F300) -> 0 | G322: =SUM(G251,G254,G256,G257,G263,G265,G266,G269,G272,G275,G276,G280,G285:G292,G295:G300) -> 0 | H322: =SUM(H251,H254,H256,H257,H263,H265,H266,H269,H272,H275,H276,H280,H285:H292,H295:H300) -> 0 | I322: =SUM(I251,I254,I256,I257,I263,I265,I266,I269,I272,I275,I276,I280,I285:I292,I295:I300) -> 0 | J322: =SUM(J251,J254,J256,J257,J263,J265,J266,J269,J272,J275,J276,J280,J285:J292,J295:J300) -> 0 | ... N322: =SUM(N251,N254,N256,N257,N263,N265,N266,N269,N272,N275,N276,N280,N285:N292,N295:N300) -> 0 | O322: =SUM(C322:N322) -> 285701.62
B323: New @ 47.517% | C323: =ROUND(C322*47.517%,2) -> 55558.48 | D323: =ROUND(D322*47.517%,2) -> 33867 | E323: =ROUND(E322*47.517%,2) -> 46331.36 | F323: =ROUND(F322*47.517%,2) -> 0 | G323: =ROUND(G322*47.517%,2) -> 0 | H323: =ROUND(H322*47.517%,2) -> 0 | I323: =ROUND(I322*47.517%,2) -> 0 | J323: =ROUND(J322*47.517%,2) -> 0 | ... N323: =ROUND(N322*47.517%,2) -> 0 | O323: =SUM(C323:N323) -> 135756.84
B324: Used @ 3.029% | C324: =ROUND(C322*3.209%,2) -> 3752.07 | D324: =ROUND(D322*3.209%,2) -> 2287.16 | E324: =ROUND(E322*3.209%,2) -> 3128.93 | F324: =ROUND(F322*3.209%,2) -> 0 | G324: =ROUND(G322*3.209%,2) -> 0 | H324: =ROUND(H322*3.209%,2) -> 0 | I324: =ROUND(I322*3.209%,2) -> 0 | J324: =ROUND(J322*3.209%,2) -> 0 | ... N324: =ROUND(N322*3.209%,2) -> 0 | O324: =SUM(C324:N324) -> 9168.16
B325: Rental @ 20.694% | C325: =ROUND(C322*20.694%,2) -> 24196.12 | D325: =ROUND(D322*20.694%,2) -> 14749.32 | E325: =ROUND(E322*20.694%,2) -> 20177.65 | F325: =ROUND(F322*20.694%,2) -> 0 | G325: =ROUND(G322*20.694%,2) -> 0 | H325: =ROUND(H322*20.694%,2) -> 0 | I325: =ROUND(I322*20.694%,2) -> 0 | J325: =ROUND(J322*20.694%,2) -> 0 | ... N325: =ROUND(N322*20.694%,2) -> 0 | O325: =SUM(C325:N325) -> 59123.09
B326: Parts @ 13.121% | C326: =ROUND(C322*13.121%,2) -> 15341.52 | D326: =ROUND(D322*13.121%,2) -> 9351.79 | E326: =ROUND(E322*13.121%,2) -> 12793.61 | F326: =ROUND(F322*13.121%,2) -> 0 | G326: =ROUND(G322*13.121%,2) -> 0 | H326: =ROUND(H322*13.121%,2) -> 0 | I326: =ROUND(I322*13.121%,2) -> 0 | J326: =ROUND(J322*13.121%,2) -> 0 | ... N326: =ROUND(N322*13.121%,2) -> 0 | O326: =SUM(C326:N326) -> 37486.92
B327: Service @ 14.953% | C327: =ROUND(C322*14.953%,2) -> 17483.55 | D327: =ROUND(D322*14.953%,2) -> 10657.52 | E327: =ROUND(E322*14.953%,2) -> 14579.89 | F327: =ROUND(F322*14.953%,2) -> 0 | G327: =ROUND(G322*14.953%,2) -> 0 | H327: =ROUND(H322*14.953%,2) -> 0 | I327: =ROUND(I322*14.953%,2) -> 0 | J327: =ROUND(J322*14.953%,2) -> 0 | ... N327: =ROUND(N322*14.953%,2) -> 0 | O327: =SUM(C327:N327) -> 42720.96
B328: Transport. @ 0.507% | C328: =ROUND(C322*0.507%,2) -> 592.8 | D328: =ROUND(D322*0.507%,2) -> 361.36 | E328: =ROUND(E322*0.507%,2) -> 494.35 | F328: =ROUND(F322*0.507%,2) -> 0 | G328: =ROUND(G322*0.507%,2) -> 0 | H328: =ROUND(H322*0.507%,2) -> 0 | I328: =ROUND(I322*0.507%,2) -> 0 | J328: =ROUND(J322*0.507%,2) -> 0 | ... N328: =ROUND(N322*0.507%,2) -> 0 | O328: =SUM(C328:N328) -> 1448.51
B329: Admin
B330: Occupancy | C330: =SUM(C252:C254,C260,C301) -> 55886.97 | D330: =SUM(D252:D254,D260,D301) -> 47486.9 | E330: =SUM(E252:E254,E260,E301) -> 71796.08 | F330: =SUM(F252:F254,F260,F301) -> 0 | G330: =SUM(G252:G254,G260,G301) -> 0 | H330: =SUM(H252:H254,H260,H301) -> 0 | I330: =SUM(I252:I254,I260,I301) -> 0 | J330: =SUM(J252:J254,J260,J301) -> 0 | ... N330: =SUM(N252:N254,N260,N301) -> 0 | O330: =SUM(C330:N330) -> 175169.95
B331: New @ 47.517% | C331: =ROUND(C330*47.517%,2) -> 26555.81 | D331: =ROUND(D330*47.517%,2) -> 22564.35 | E331: =ROUND(E330*47.517%,2) -> 34115.34 | F331: =ROUND(F330*47.517%,2) -> 0 | G331: =ROUND(G330*47.517%,2) -> 0 | H331: =ROUND(H330*47.517%,2) -> 0 | I331: =ROUND(I330*47.517%,2) -> 0 | J331: =ROUND(J330*47.517%,2) -> 0 | ... N331: =ROUND(N330*47.517%,2) -> 0 | O331: =SUM(C331:N331) -> 83235.5
B332: Used @ 3.029% | C332: =ROUND(C330*3.209%,2) -> 1793.41 | D332: =ROUND(D330*3.209%,2) -> 1523.85 | E332: =ROUND(E330*3.209%,2) -> 2303.94 | F332: =ROUND(F330*3.209%,2) -> 0 | G332: =ROUND(G330*3.209%,2) -> 0 | H332: =ROUND(H330*3.209%,2) -> 0 | I332: =ROUND(I330*3.209%,2) -> 0 | J332: =ROUND(J330*3.209%,2) -> 0 | ... N332: =ROUND(N330*3.209%,2) -> 0 | O332: =SUM(C332:N332) -> 5621.2
B333: Rental @ 20.694% | C333: =ROUND(C330*20.694%,2) -> 11565.25 | D333: =ROUND(D330*20.694%,2) -> 9826.94 | E333: =ROUND(E330*20.694%,2) -> 14857.48 | F333: =ROUND(F330*20.694%,2) -> 0 | G333: =ROUND(G330*20.694%,2) -> 0 | H333: =ROUND(H330*20.694%,2) -> 0 | I333: =ROUND(I330*20.694%,2) -> 0 | J333: =ROUND(J330*20.694%,2) -> 0 | ... N333: =ROUND(N330*20.694%,2) -> 0 | O333: =SUM(C333:N333) -> 36249.67
B334: Parts @ 13.121% | C334: =ROUND(C330*13.121%,2) -> 7332.93 | D334: =ROUND(D330*13.121%,2) -> 6230.76 | E334: =ROUND(E330*13.121%,2) -> 9420.36 | F334: =ROUND(F330*13.121%,2) -> 0 | G334: =ROUND(G330*13.121%,2) -> 0 | H334: =ROUND(H330*13.121%,2) -> 0 | I334: =ROUND(I330*13.121%,2) -> 0 | J334: =ROUND(J330*13.121%,2) -> 0 | ... N334: =ROUND(N330*13.121%,2) -> 0 | O334: =SUM(C334:N334) -> 22984.05
B335: Service @ 14.953% | C335: =ROUND(C330*14.953%,2) -> 8356.78 | D335: =ROUND(D330*14.953%,2) -> 7100.72 | E335: =ROUND(E330*14.953%,2) -> 10735.67 | F335: =ROUND(F330*14.953%,2) -> 0 | G335: =ROUND(G330*14.953%,2) -> 0 | H335: =ROUND(H330*14.953%,2) -> 0 | I335: =ROUND(I330*14.953%,2) -> 0 | J335: =ROUND(J330*14.953%,2) -> 0 | ... N335: =ROUND(N330*14.953%,2) -> 0 | O335: =SUM(C335:N335) -> 26193.17
B336: Transport. @ 0.507% | C336: =ROUND(C330*0.507%,2) -> 283.35 | D336: =ROUND(D330*0.507%,2) -> 240.76 | E336: =ROUND(E330*0.507%,2) -> 364.01 | F336: =ROUND(F330*0.507%,2) -> 0 | G336: =ROUND(G330*0.507%,2) -> 0 | H336: =ROUND(H330*0.507%,2) -> 0 | I336: =ROUND(I330*0.507%,2) -> 0 | J336: =ROUND(J330*0.507%,2) -> 0 | ... N336: =ROUND(N330*0.507%,2) -> 0 | O336: =SUM(C336:N336) -> 888.12
B337: Admin

Sheet NumberOfMonths
A1: 1
A2: 2
A3: 3
A4: 4
A5: 5
A6: 6
A7: 7
A8: 8
A9: 9
A10: 10
A11: 11
A12: 12
